2020-04-27 09:27:28,901 (util.py:66 PollingThread) ERROR - TeleBot: "ApiException occurred, args=('A request to the Telegram API was unsuccessful. The server returned HTTP 409 Conflict. Response body:\n[b\'{"ok":false,"error_code":409,"description":"Conflict: terminated by other getUpdates request; make sure that only one bot instance is running"}\']',)
Traceback (most recent call last):
  File "/usr/local/lib/python3.5/dist-packages/telebot/util.py", line 60, in run
    task(*args, **kwargs)
  File "/usr/local/lib/python3.5/dist-packages/telebot/__init__.py", line 279, in __retrieve_updates
    updates = self.get_updates(offset=(self.last_update_id + 1), timeout=timeout)
  File "/usr/local/lib/python3.5/dist-packages/telebot/__init__.py", line 249, in get_updates
    json_updates = apihelper.get_updates(self.token, offset, limit, timeout, allowed_updates)
  File "/usr/local/lib/python3.5/dist-packages/telebot/apihelper.py", line 194, in get_updates
    return _make_request(token, method_url, params=payload)
  File "/usr/local/lib/python3.5/dist-packages/telebot/apihelper.py", line 60, in _make_request
    return _check_result(method_name, result)['result']
  File "/usr/local/lib/python3.5/dist-packages/telebot/apihelper.py", line 79, in _check_result
    raise ApiException(msg, method_name, result)
telebot.apihelper.ApiException: A request to the Telegram API was unsuccessful. The server returned HTTP 409 Conflict. Response body:
[b'{"ok":false,"error_code":409,"description":"Conflict: terminated by other getUpdates request; make sure that only one bot instance is running"}']
"
2020-04-27 09:27:28,901 (__init__.py:420 MainThread) ERROR - TeleBot: "A request to the Telegram API was unsuccessful. The server returned HTTP 409 Conflict. Response body:
[b'{"ok":false,"error_code":409,"description":"Conflict: terminated by other getUpdates request; make sure that only one bot instance is running"}']"
2020-04-27 09:28:22,720 (util.py:66 PollingThread) ERROR - TeleBot: "ApiException occurred, args=('A request to the Telegram API was unsuccessful. The server returned HTTP 409 Conflict. Response body:\n[b\'{"ok":false,"error_code":409,"description":"Conflict: terminated by other getUpdates request; make sure that only one bot instance is running"}\']',)
Traceback (most recent call last):
  File "/usr/local/lib/python3.5/dist-packages/telebot/util.py", line 60, in run
    task(*args, **kwargs)
  File "/usr/local/lib/python3.5/dist-packages/telebot/__init__.py", line 279, in __retrieve_updates
    updates = self.get_updates(offset=(self.last_update_id + 1), timeout=timeout)
  File "/usr/local/lib/python3.5/dist-packages/telebot/__init__.py", line 249, in get_updates
    json_updates = apihelper.get_updates(self.token, offset, limit, timeout, allowed_updates)
  File "/usr/local/lib/python3.5/dist-packages/telebot/apihelper.py", line 194, in get_updates
    return _make_request(token, method_url, params=payload)
  File "/usr/local/lib/python3.5/dist-packages/telebot/apihelper.py", line 60, in _make_request
    return _check_result(method_name, result)['result']
  File "/usr/local/lib/python3.5/dist-packages/telebot/apihelper.py", line 79, in _check_result
    raise ApiException(msg, method_name, result)
telebot.apihelper.ApiException: A request to the Telegram API was unsuccessful. The server returned HTTP 409 Conflict. Response body:
[b'{"ok":false,"error_code":409,"description":"Conflict: terminated by other getUpdates request; make sure that only one bot instance is running"}']
"
2020-04-27 09:28:22,720 (__init__.py:420 MainThread) ERROR - TeleBot: "A request to the Telegram API was unsuccessful. The server returned HTTP 409 Conflict. Response body:
[b'{"ok":false,"error_code":409,"description":"Conflict: terminated by other getUpdates request; make sure that only one bot instance is running"}']"
2020-04-27 09:28:31,859 (util.py:66 WorkerThread2) ERROR - TeleBot: "ApiException occurred, args=('A request to the Telegram API was unsuccessful. The server returned HTTP 403 Forbidden. Response body:\n[b\'{"ok":false,"error_code":403,"description":"Forbidden: bot can\\\'t initiate conversation with a user"}\']',)
Traceback (most recent call last):
  File "/usr/local/lib/python3.5/dist-packages/telebot/util.py", line 60, in run
    task(*args, **kwargs)
  File "main.py", line 83, in everybody
    bot.send_message(A_ID, "Andryusha idi nahui i zaidi v konfu plis")
  File "/usr/local/lib/python3.5/dist-packages/telebot/__init__.py", line 601, in send_message
    reply_markup, parse_mode, disable_notification, timeout))
  File "/usr/local/lib/python3.5/dist-packages/telebot/apihelper.py", line 154, in send_message
    return _make_request(token, method_url, params=payload, method='post')
  File "/usr/local/lib/python3.5/dist-packages/telebot/apihelper.py", line 60, in _make_request
    return _check_result(method_name, result)['result']
  File "/usr/local/lib/python3.5/dist-packages/telebot/apihelper.py", line 79, in _check_result
    raise ApiException(msg, method_name, result)
telebot.apihelper.ApiException: A request to the Telegram API was unsuccessful. The server returned HTTP 403 Forbidden. Response body:
[b'{"ok":false,"error_code":403,"description":"Forbidden: bot can\'t initiate conversation with a user"}']
"
2020-04-27 09:28:31,860 (__init__.py:420 MainThread) ERROR - TeleBot: "A request to the Telegram API was unsuccessful. The server returned HTTP 403 Forbidden. Response body:
[b'{"ok":false,"error_code":403,"description":"Forbidden: bot can\'t initiate conversation with a user"}']"
2020-04-27 09:32:00,530 (util.py:66 WorkerThread2) ERROR - TeleBot: "ApiException occurred, args=('A request to the Telegram API was unsuccessful. The server returned HTTP 403 Forbidden. Response body:\n[b\'{"ok":false,"error_code":403,"description":"Forbidden: bot can\\\'t initiate conversation with a user"}\']',)
Traceback (most recent call last):
  File "/usr/local/lib/python3.5/dist-packages/telebot/util.py", line 60, in run
    task(*args, **kwargs)
  File "main.py", line 84, in everybody
    bot.send_message(A_ID, "Andryusha " + s)
  File "/usr/local/lib/python3.5/dist-packages/telebot/__init__.py", line 601, in send_message
    reply_markup, parse_mode, disable_notification, timeout))
  File "/usr/local/lib/python3.5/dist-packages/telebot/apihelper.py", line 154, in send_message
    return _make_request(token, method_url, params=payload, method='post')
  File "/usr/local/lib/python3.5/dist-packages/telebot/apihelper.py", line 60, in _make_request
    return _check_result(method_name, result)['result']
  File "/usr/local/lib/python3.5/dist-packages/telebot/apihelper.py", line 79, in _check_result
    raise ApiException(msg, method_name, result)
telebot.apihelper.ApiException: A request to the Telegram API was unsuccessful. The server returned HTTP 403 Forbidden. Response body:
[b'{"ok":false,"error_code":403,"description":"Forbidden: bot can\'t initiate conversation with a user"}']
"
2020-04-27 09:32:00,531 (__init__.py:420 MainThread) ERROR - TeleBot: "A request to the Telegram API was unsuccessful. The server returned HTTP 403 Forbidden. Response body:
[b'{"ok":false,"error_code":403,"description":"Forbidden: bot can\'t initiate conversation with a user"}']"
2020-04-27 10:28:42,933 (util.py:66 WorkerThread1) ERROR - TeleBot: "ApiException occurred, args=('A request to the Telegram API was unsuccessful. The server returned HTTP 403 Forbidden. Response body:\n[b\'{"ok":false,"error_code":403,"description":"Forbidden: bot can\\\'t initiate conversation with a user"}\']',)
Traceback (most recent call last):
  File "/usr/local/lib/python3.5/dist-packages/telebot/util.py", line 60, in run
    task(*args, **kwargs)
  File "main.py", line 84, in everybody
    bot.send_message(A_ID, "Andryusha " + s)
  File "/usr/local/lib/python3.5/dist-packages/telebot/__init__.py", line 601, in send_message
    reply_markup, parse_mode, disable_notification, timeout))
  File "/usr/local/lib/python3.5/dist-packages/telebot/apihelper.py", line 154, in send_message
    return _make_request(token, method_url, params=payload, method='post')
  File "/usr/local/lib/python3.5/dist-packages/telebot/apihelper.py", line 60, in _make_request
    return _check_result(method_name, result)['result']
  File "/usr/local/lib/python3.5/dist-packages/telebot/apihelper.py", line 79, in _check_result
    raise ApiException(msg, method_name, result)
telebot.apihelper.ApiException: A request to the Telegram API was unsuccessful. The server returned HTTP 403 Forbidden. Response body:
[b'{"ok":false,"error_code":403,"description":"Forbidden: bot can\'t initiate conversation with a user"}']
"
2020-04-27 10:28:42,934 (__init__.py:420 MainThread) ERROR - TeleBot: "A request to the Telegram API was unsuccessful. The server returned HTTP 403 Forbidden. Response body:
[b'{"ok":false,"error_code":403,"description":"Forbidden: bot can\'t initiate conversation with a user"}']"
2020-04-27 10:29:48,828 (util.py:66 PollingThread) ERROR - TeleBot: "ApiException occurred, args=('A request to the Telegram API was unsuccessful. The server returned HTTP 409 Conflict. Response body:\n[b\'{"ok":false,"error_code":409,"description":"Conflict: terminated by other getUpdates request; make sure that only one bot instance is running"}\']',)
Traceback (most recent call last):
  File "/usr/local/lib/python3.5/dist-packages/telebot/util.py", line 60, in run
    task(*args, **kwargs)
  File "/usr/local/lib/python3.5/dist-packages/telebot/__init__.py", line 279, in __retrieve_updates
    updates = self.get_updates(offset=(self.last_update_id + 1), timeout=timeout)
  File "/usr/local/lib/python3.5/dist-packages/telebot/__init__.py", line 249, in get_updates
    json_updates = apihelper.get_updates(self.token, offset, limit, timeout, allowed_updates)
  File "/usr/local/lib/python3.5/dist-packages/telebot/apihelper.py", line 194, in get_updates
    return _make_request(token, method_url, params=payload)
  File "/usr/local/lib/python3.5/dist-packages/telebot/apihelper.py", line 60, in _make_request
    return _check_result(method_name, result)['result']
  File "/usr/local/lib/python3.5/dist-packages/telebot/apihelper.py", line 79, in _check_result
    raise ApiException(msg, method_name, result)
telebot.apihelper.ApiException: A request to the Telegram API was unsuccessful. The server returned HTTP 409 Conflict. Response body:
[b'{"ok":false,"error_code":409,"description":"Conflict: terminated by other getUpdates request; make sure that only one bot instance is running"}']
"
2020-04-27 10:29:48,828 (__init__.py:420 MainThread) ERROR - TeleBot: "A request to the Telegram API was unsuccessful. The server returned HTTP 409 Conflict. Response body:
[b'{"ok":false,"error_code":409,"description":"Conflict: terminated by other getUpdates request; make sure that only one bot instance is running"}']"
2020-04-27 10:29:54,076 (util.py:66 WorkerThread2) ERROR - TeleBot: "ApiException occurred, args=('A request to the Telegram API was unsuccessful. The server returned HTTP 403 Forbidden. Response body:\n[b\'{"ok":false,"error_code":403,"description":"Forbidden: bot can\\\'t initiate conversation with a user"}\']',)
Traceback (most recent call last):
  File "/usr/local/lib/python3.5/dist-packages/telebot/util.py", line 60, in run
    task(*args, **kwargs)
  File "main.py", line 84, in everybody
    bot.send_message(A_ID, "Andryusha " + s)
  File "/usr/local/lib/python3.5/dist-packages/telebot/__init__.py", line 601, in send_message
    reply_markup, parse_mode, disable_notification, timeout))
  File "/usr/local/lib/python3.5/dist-packages/telebot/apihelper.py", line 154, in send_message
    return _make_request(token, method_url, params=payload, method='post')
  File "/usr/local/lib/python3.5/dist-packages/telebot/apihelper.py", line 60, in _make_request
    return _check_result(method_name, result)['result']
  File "/usr/local/lib/python3.5/dist-packages/telebot/apihelper.py", line 79, in _check_result
    raise ApiException(msg, method_name, result)
telebot.apihelper.ApiException: A request to the Telegram API was unsuccessful. The server returned HTTP 403 Forbidden. Response body:
[b'{"ok":false,"error_code":403,"description":"Forbidden: bot can\'t initiate conversation with a user"}']
"
2020-04-27 10:29:54,076 (__init__.py:420 MainThread) ERROR - TeleBot: "A request to the Telegram API was unsuccessful. The server returned HTTP 403 Forbidden. Response body:
[b'{"ok":false,"error_code":403,"description":"Forbidden: bot can\'t initiate conversation with a user"}']"
2020-05-04 23:24:11,499 (util.py:66 PollingThread) ERROR - TeleBot: "ApiException occurred, args=('A request to the Telegram API was unsuccessful. The server returned HTTP 500 Internal Server Error. Response body:\n[b\'{"ok":false,"error_code":500,"description":"Internal server error: restart"}\']',)
Traceback (most recent call last):
  File "/usr/local/lib/python3.5/dist-packages/telebot/util.py", line 60, in run
    task(*args, **kwargs)
  File "/usr/local/lib/python3.5/dist-packages/telebot/__init__.py", line 279, in __retrieve_updates
    updates = self.get_updates(offset=(self.last_update_id + 1), timeout=timeout)
  File "/usr/local/lib/python3.5/dist-packages/telebot/__init__.py", line 249, in get_updates
    json_updates = apihelper.get_updates(self.token, offset, limit, timeout, allowed_updates)
  File "/usr/local/lib/python3.5/dist-packages/telebot/apihelper.py", line 194, in get_updates
    return _make_request(token, method_url, params=payload)
  File "/usr/local/lib/python3.5/dist-packages/telebot/apihelper.py", line 60, in _make_request
    return _check_result(method_name, result)['result']
  File "/usr/local/lib/python3.5/dist-packages/telebot/apihelper.py", line 79, in _check_result
    raise ApiException(msg, method_name, result)
telebot.apihelper.ApiException: A request to the Telegram API was unsuccessful. The server returned HTTP 500 Internal Server Error. Response body:
[b'{"ok":false,"error_code":500,"description":"Internal server error: restart"}']
"
2020-05-04 23:24:11,500 (__init__.py:420 MainThread) ERROR - TeleBot: "A request to the Telegram API was unsuccessful. The server returned HTTP 500 Internal Server Error. Response body:
[b'{"ok":false,"error_code":500,"description":"Internal server error: restart"}']"
  File "Pika.py", line 7
SyntaxError: Non-UTF-8 code starting with '\xea' in file Pika.py on line 7, but no encoding declared; see http://python.org/dev/peps/pep-0263/ for details
2020-05-06 15:58:14,718 (util.py:66 WorkerThread2) ERROR - TeleBot: "ApiException occurred, args=('A request to the Telegram API was unsuccessful. The server returned HTTP 400 Bad Request. Response body:\n[b\'{"ok":false,"error_code":400,"description":"Bad Request: chat not found"}\']',)
Traceback (most recent call last):
  File "/usr/local/lib/python3.5/dist-packages/telebot/util.py", line 60, in run
    task(*args, **kwargs)
  File "main.py", line 84, in everybody
    bot.send_message(A_ID, "Andryusha " + s)
  File "/usr/local/lib/python3.5/dist-packages/telebot/__init__.py", line 601, in send_message
    reply_markup, parse_mode, disable_notification, timeout))
  File "/usr/local/lib/python3.5/dist-packages/telebot/apihelper.py", line 154, in send_message
    return _make_request(token, method_url, params=payload, method='post')
  File "/usr/local/lib/python3.5/dist-packages/telebot/apihelper.py", line 60, in _make_request
    return _check_result(method_name, result)['result']
  File "/usr/local/lib/python3.5/dist-packages/telebot/apihelper.py", line 79, in _check_result
    raise ApiException(msg, method_name, result)
telebot.apihelper.ApiException: A request to the Telegram API was unsuccessful. The server returned HTTP 400 Bad Request. Response body:
[b'{"ok":false,"error_code":400,"description":"Bad Request: chat not found"}']
"
2020-05-06 15:58:14,718 (__init__.py:420 MainThread) ERROR - TeleBot: "A request to the Telegram API was unsuccessful. The server returned HTTP 400 Bad Request. Response body:
[b'{"ok":false,"error_code":400,"description":"Bad Request: chat not found"}']"
2020-05-06 16:01:24,205 (util.py:66 WorkerThread1) ERROR - TeleBot: "ApiException occurred, args=('A request to the Telegram API was unsuccessful. The server returned HTTP 400 Bad Request. Response body:\n[b\'{"ok":false,"error_code":400,"description":"Bad Request: chat not found"}\']',)
Traceback (most recent call last):
  File "/usr/local/lib/python3.5/dist-packages/telebot/util.py", line 60, in run
    task(*args, **kwargs)
  File "main.py", line 84, in everybody
    bot.send_message(A_ID, "Andryusha " + s)
  File "/usr/local/lib/python3.5/dist-packages/telebot/__init__.py", line 601, in send_message
    reply_markup, parse_mode, disable_notification, timeout))
  File "/usr/local/lib/python3.5/dist-packages/telebot/apihelper.py", line 154, in send_message
    return _make_request(token, method_url, params=payload, method='post')
  File "/usr/local/lib/python3.5/dist-packages/telebot/apihelper.py", line 60, in _make_request
    return _check_result(method_name, result)['result']
  File "/usr/local/lib/python3.5/dist-packages/telebot/apihelper.py", line 79, in _check_result
    raise ApiException(msg, method_name, result)
telebot.apihelper.ApiException: A request to the Telegram API was unsuccessful. The server returned HTTP 400 Bad Request. Response body:
[b'{"ok":false,"error_code":400,"description":"Bad Request: chat not found"}']
"
2020-05-06 16:01:24,206 (__init__.py:420 MainThread) ERROR - TeleBot: "A request to the Telegram API was unsuccessful. The server returned HTTP 400 Bad Request. Response body:
[b'{"ok":false,"error_code":400,"description":"Bad Request: chat not found"}']"
2020-05-06 16:06:40,002 (util.py:66 PollingThread) ERROR - TeleBot: "ApiException occurred, args=('A request to the Telegram API was unsuccessful. The server returned HTTP 409 Conflict. Response body:\n[b\'{"ok":false,"error_code":409,"description":"Conflict: terminated by other getUpdates request; make sure that only one bot instance is running"}\']',)
Traceback (most recent call last):
  File "/usr/local/lib/python3.5/dist-packages/telebot/util.py", line 60, in run
    task(*args, **kwargs)
  File "/usr/local/lib/python3.5/dist-packages/telebot/__init__.py", line 279, in __retrieve_updates
    updates = self.get_updates(offset=(self.last_update_id + 1), timeout=timeout)
  File "/usr/local/lib/python3.5/dist-packages/telebot/__init__.py", line 249, in get_updates
    json_updates = apihelper.get_updates(self.token, offset, limit, timeout, allowed_updates)
  File "/usr/local/lib/python3.5/dist-packages/telebot/apihelper.py", line 194, in get_updates
    return _make_request(token, method_url, params=payload)
  File "/usr/local/lib/python3.5/dist-packages/telebot/apihelper.py", line 60, in _make_request
    return _check_result(method_name, result)['result']
  File "/usr/local/lib/python3.5/dist-packages/telebot/apihelper.py", line 79, in _check_result
    raise ApiException(msg, method_name, result)
telebot.apihelper.ApiException: A request to the Telegram API was unsuccessful. The server returned HTTP 409 Conflict. Response body:
[b'{"ok":false,"error_code":409,"description":"Conflict: terminated by other getUpdates request; make sure that only one bot instance is running"}']
"
2020-05-06 16:06:40,003 (__init__.py:420 MainThread) ERROR - TeleBot: "A request to the Telegram API was unsuccessful. The server returned HTTP 409 Conflict. Response body:
[b'{"ok":false,"error_code":409,"description":"Conflict: terminated by other getUpdates request; make sure that only one bot instance is running"}']"
2020-05-06 16:06:46,348 (util.py:66 WorkerThread1) ERROR - TeleBot: "ApiException occurred, args=('A request to the Telegram API was unsuccessful. The server returned HTTP 400 Bad Request. Response body:\n[b\'{"ok":false,"error_code":400,"description":"Bad Request: chat not found"}\']',)
Traceback (most recent call last):
  File "/usr/local/lib/python3.5/dist-packages/telebot/util.py", line 60, in run
    task(*args, **kwargs)
  File "main.py", line 85, in everybody
    bot.send_message(A_ID, "Andryusha " + s)
  File "/usr/local/lib/python3.5/dist-packages/telebot/__init__.py", line 601, in send_message
    reply_markup, parse_mode, disable_notification, timeout))
  File "/usr/local/lib/python3.5/dist-packages/telebot/apihelper.py", line 154, in send_message
    return _make_request(token, method_url, params=payload, method='post')
  File "/usr/local/lib/python3.5/dist-packages/telebot/apihelper.py", line 60, in _make_request
    return _check_result(method_name, result)['result']
  File "/usr/local/lib/python3.5/dist-packages/telebot/apihelper.py", line 79, in _check_result
    raise ApiException(msg, method_name, result)
telebot.apihelper.ApiException: A request to the Telegram API was unsuccessful. The server returned HTTP 400 Bad Request. Response body:
[b'{"ok":false,"error_code":400,"description":"Bad Request: chat not found"}']
"
2020-05-06 16:06:46,349 (__init__.py:420 MainThread) ERROR - TeleBot: "A request to the Telegram API was unsuccessful. The server returned HTTP 400 Bad Request. Response body:
[b'{"ok":false,"error_code":400,"description":"Bad Request: chat not found"}']"
2020-05-06 16:13:14,710 (util.py:66 WorkerThread2) ERROR - TeleBot: "NameError occurred, args=("name 'sleep' is not defined",)
Traceback (most recent call last):
  File "/usr/local/lib/python3.5/dist-packages/telebot/util.py", line 60, in run
    task(*args, **kwargs)
  File "main.py", line 83, in everybody
    sleep(1)
NameError: name 'sleep' is not defined
"
Traceback (most recent call last):
  File "main.py", line 180, in <module>
    bot.polling()
  File "/usr/local/lib/python3.5/dist-packages/telebot/__init__.py", line 392, in polling
    self.__threaded_polling(none_stop, interval, timeout)
  File "/usr/local/lib/python3.5/dist-packages/telebot/__init__.py", line 416, in __threaded_polling
    self.worker_pool.raise_exceptions()
  File "/usr/local/lib/python3.5/dist-packages/telebot/util.py", line 109, in raise_exceptions
    six.reraise(self.exc_info[0], self.exc_info[1], self.exc_info[2])
  File "/usr/lib/python3/dist-packages/six.py", line 686, in reraise
    raise value
  File "/usr/local/lib/python3.5/dist-packages/telebot/util.py", line 60, in run
    task(*args, **kwargs)
  File "main.py", line 83, in everybody
    sleep(1)
NameError: name 'sleep' is not defined
2020-05-06 16:23:48,718 (util.py:66 WorkerThread2) ERROR - TeleBot: "NameError occurred, args=("name 'sleep' is not defined",)
Traceback (most recent call last):
  File "/usr/local/lib/python3.5/dist-packages/telebot/util.py", line 60, in run
    task(*args, **kwargs)
  File "main.py", line 85, in everybody
    sleep(1)
NameError: name 'sleep' is not defined
"
Traceback (most recent call last):
  File "main.py", line 183, in <module>
    bot.polling()
  File "/usr/local/lib/python3.5/dist-packages/telebot/__init__.py", line 392, in polling
    self.__threaded_polling(none_stop, interval, timeout)
  File "/usr/local/lib/python3.5/dist-packages/telebot/__init__.py", line 416, in __threaded_polling
    self.worker_pool.raise_exceptions()
  File "/usr/local/lib/python3.5/dist-packages/telebot/util.py", line 109, in raise_exceptions
    six.reraise(self.exc_info[0], self.exc_info[1], self.exc_info[2])
  File "/usr/lib/python3/dist-packages/six.py", line 686, in reraise
    raise value
  File "/usr/local/lib/python3.5/dist-packages/telebot/util.py", line 60, in run
    task(*args, **kwargs)
  File "main.py", line 85, in everybody
    sleep(1)
NameError: name 'sleep' is not defined
dictionary.txt
history-1001229537008.txt
history-1001335011853.txt
history374545615.txt
history-462677153.txt
main.py
nohup.out
Pika.py
script.sh
2020-05-06 16:24:47,727 (util.py:66 WorkerThread1) ERROR - TeleBot: "ApiException occurred, args=('A request to the Telegram API was unsuccessful. The server returned HTTP 400 Bad Request. Response body:\n[b\'{"ok":false,"error_code":400,"description":"Bad Request: chat not found"}\']',)
Traceback (most recent call last):
  File "/usr/local/lib/python3.5/dist-packages/telebot/util.py", line 60, in run
    task(*args, **kwargs)
  File "main.py", line 91, in everybody
    bot.send_message(A_ID, "Andryusha " + s)
  File "/usr/local/lib/python3.5/dist-packages/telebot/__init__.py", line 601, in send_message
    reply_markup, parse_mode, disable_notification, timeout))
  File "/usr/local/lib/python3.5/dist-packages/telebot/apihelper.py", line 154, in send_message
    return _make_request(token, method_url, params=payload, method='post')
  File "/usr/local/lib/python3.5/dist-packages/telebot/apihelper.py", line 60, in _make_request
    return _check_result(method_name, result)['result']
  File "/usr/local/lib/python3.5/dist-packages/telebot/apihelper.py", line 79, in _check_result
    raise ApiException(msg, method_name, result)
telebot.apihelper.ApiException: A request to the Telegram API was unsuccessful. The server returned HTTP 400 Bad Request. Response body:
[b'{"ok":false,"error_code":400,"description":"Bad Request: chat not found"}']
"
2020-05-06 16:24:47,727 (__init__.py:420 MainThread) ERROR - TeleBot: "A request to the Telegram API was unsuccessful. The server returned HTTP 400 Bad Request. Response body:
[b'{"ok":false,"error_code":400,"description":"Bad Request: chat not found"}']"
total 136
drwxr-xr-x 3 root root  4096 May  6 16:26 .
drwx------ 7 root root  4096 May  6 16:26 ..
-rw-r--r-- 1 root root 24045 Apr 27 09:19 dictionary.txt
drwxr-xr-x 8 root root  4096 Apr 24 07:35 .git
-rw-r--r-- 1 root root   911 Apr 28 08:08 history-1001229537008.txt
-rw-r--r-- 1 root root 20934 Apr 27 10:33 history-1001335011853.txt
-rw-r--r-- 1 root root    79 Apr 23 15:00 history374545615.txt
-rw-r--r-- 1 root root  6609 Apr 24 08:18 history-462677153.txt
-rw-r--r-- 1 root root  5754 May  6 16:26 main.py
-rw------- 1 root root 25463 May  6 16:24 nohup.out
-rw-r--r-- 1 root root 15648 Apr 23 15:52 Pika.py
-rw-r--r-- 1 root root   220 May  6 16:19 script.sh
total 136
drwxr-xr-x 3 root root  4096 May  6 16:26 .
drwx------ 7 root root  4096 May  6 16:26 ..
-rw-r--r-- 1 root root 24045 Apr 27 09:19 dictionary.txt
drwxr-xr-x 8 root root  4096 Apr 24 07:35 .git
-rw-r--r-- 1 root root   911 Apr 28 08:08 history-1001229537008.txt
-rw-r--r-- 1 root root 20934 Apr 27 10:33 history-1001335011853.txt
-rw-r--r-- 1 root root    79 Apr 23 15:00 history374545615.txt
-rw-r--r-- 1 root root  6609 Apr 24 08:18 history-462677153.txt
-rw-r--r-- 1 root root  5754 May  6 16:26 main.py
-rw------- 1 root root 26133 May  6 16:26 nohup.out
-rw-r--r-- 1 root root 15648 Apr 23 15:52 Pika.py
-rw-r--r-- 1 root root   220 May  6 16:19 script.sh
2020-05-06 16:26:24,539 (util.py:66 WorkerThread1) ERROR - TeleBot: "ApiException occurred, args=('A request to the Telegram API was unsuccessful. The server returned HTTP 400 Bad Request. Response body:\n[b\'{"ok":false,"error_code":400,"description":"Bad Request: chat not found"}\']',)
Traceback (most recent call last):
  File "/usr/local/lib/python3.5/dist-packages/telebot/util.py", line 60, in run
    task(*args, **kwargs)
  File "main.py", line 91, in everybody
    bot.send_message(A_ID, "Andryusha " + s)
  File "/usr/local/lib/python3.5/dist-packages/telebot/__init__.py", line 601, in send_message
    reply_markup, parse_mode, disable_notification, timeout))
  File "/usr/local/lib/python3.5/dist-packages/telebot/apihelper.py", line 154, in send_message
    return _make_request(token, method_url, params=payload, method='post')
  File "/usr/local/lib/python3.5/dist-packages/telebot/apihelper.py", line 60, in _make_request
    return _check_result(method_name, result)['result']
  File "/usr/local/lib/python3.5/dist-packages/telebot/apihelper.py", line 79, in _check_result
    raise ApiException(msg, method_name, result)
telebot.apihelper.ApiException: A request to the Telegram API was unsuccessful. The server returned HTTP 400 Bad Request. Response body:
[b'{"ok":false,"error_code":400,"description":"Bad Request: chat not found"}']
"
2020-05-06 16:26:24,540 (__init__.py:420 MainThread) ERROR - TeleBot: "A request to the Telegram API was unsuccessful. The server returned HTTP 400 Bad Request. Response body:
[b'{"ok":false,"error_code":400,"description":"Bad Request: chat not found"}']"
2020-05-06 16:45:18,583 (util.py:66 PollingThread) ERROR - TeleBot: "ApiException occurred, args=('A request to the Telegram API was unsuccessful. The server returned HTTP 409 Conflict. Response body:\n[b\'{"ok":false,"error_code":409,"description":"Conflict: terminated by other getUpdates request; make sure that only one bot instance is running"}\']',)
Traceback (most recent call last):
  File "/usr/local/lib/python3.5/dist-packages/telebot/util.py", line 60, in run
    task(*args, **kwargs)
  File "/usr/local/lib/python3.5/dist-packages/telebot/__init__.py", line 279, in __retrieve_updates
    updates = self.get_updates(offset=(self.last_update_id + 1), timeout=timeout)
  File "/usr/local/lib/python3.5/dist-packages/telebot/__init__.py", line 249, in get_updates
    json_updates = apihelper.get_updates(self.token, offset, limit, timeout, allowed_updates)
  File "/usr/local/lib/python3.5/dist-packages/telebot/apihelper.py", line 194, in get_updates
    return _make_request(token, method_url, params=payload)
  File "/usr/local/lib/python3.5/dist-packages/telebot/apihelper.py", line 60, in _make_request
    return _check_result(method_name, result)['result']
  File "/usr/local/lib/python3.5/dist-packages/telebot/apihelper.py", line 79, in _check_result
    raise ApiException(msg, method_name, result)
telebot.apihelper.ApiException: A request to the Telegram API was unsuccessful. The server returned HTTP 409 Conflict. Response body:
[b'{"ok":false,"error_code":409,"description":"Conflict: terminated by other getUpdates request; make sure that only one bot instance is running"}']
"
2020-05-06 16:45:18,584 (__init__.py:420 MainThread) ERROR - TeleBot: "A request to the Telegram API was unsuccessful. The server returned HTTP 409 Conflict. Response body:
[b'{"ok":false,"error_code":409,"description":"Conflict: terminated by other getUpdates request; make sure that only one bot instance is running"}']"
2020-05-06 16:52:17,844 (util.py:66 PollingThread) ERROR - TeleBot: "ApiException occurred, args=('A request to the Telegram API was unsuccessful. The server returned HTTP 409 Conflict. Response body:\n[b\'{"ok":false,"error_code":409,"description":"Conflict: terminated by other getUpdates request; make sure that only one bot instance is running"}\']',)
Traceback (most recent call last):
  File "/usr/local/lib/python3.5/dist-packages/telebot/util.py", line 60, in run
    task(*args, **kwargs)
  File "/usr/local/lib/python3.5/dist-packages/telebot/__init__.py", line 279, in __retrieve_updates
    updates = self.get_updates(offset=(self.last_update_id + 1), timeout=timeout)
  File "/usr/local/lib/python3.5/dist-packages/telebot/__init__.py", line 249, in get_updates
    json_updates = apihelper.get_updates(self.token, offset, limit, timeout, allowed_updates)
  File "/usr/local/lib/python3.5/dist-packages/telebot/apihelper.py", line 194, in get_updates
    return _make_request(token, method_url, params=payload)
  File "/usr/local/lib/python3.5/dist-packages/telebot/apihelper.py", line 60, in _make_request
    return _check_result(method_name, result)['result']
  File "/usr/local/lib/python3.5/dist-packages/telebot/apihelper.py", line 79, in _check_result
    raise ApiException(msg, method_name, result)
telebot.apihelper.ApiException: A request to the Telegram API was unsuccessful. The server returned HTTP 409 Conflict. Response body:
[b'{"ok":false,"error_code":409,"description":"Conflict: terminated by other getUpdates request; make sure that only one bot instance is running"}']
"
2020-05-06 16:52:17,845 (__init__.py:420 MainThread) ERROR - TeleBot: "A request to the Telegram API was unsuccessful. The server returned HTTP 409 Conflict. Response body:
[b'{"ok":false,"error_code":409,"description":"Conflict: terminated by other getUpdates request; make sure that only one bot instance is running"}']"
2020-05-06 16:53:02,709 (util.py:66 PollingThread) ERROR - TeleBot: "ApiException occurred, args=('A request to the Telegram API was unsuccessful. The server returned HTTP 409 Conflict. Response body:\n[b\'{"ok":false,"error_code":409,"description":"Conflict: terminated by other getUpdates request; make sure that only one bot instance is running"}\']',)
Traceback (most recent call last):
  File "/usr/local/lib/python3.5/dist-packages/telebot/util.py", line 60, in run
    task(*args, **kwargs)
  File "/usr/local/lib/python3.5/dist-packages/telebot/__init__.py", line 279, in __retrieve_updates
    updates = self.get_updates(offset=(self.last_update_id + 1), timeout=timeout)
  File "/usr/local/lib/python3.5/dist-packages/telebot/__init__.py", line 249, in get_updates
    json_updates = apihelper.get_updates(self.token, offset, limit, timeout, allowed_updates)
  File "/usr/local/lib/python3.5/dist-packages/telebot/apihelper.py", line 194, in get_updates
    return _make_request(token, method_url, params=payload)
  File "/usr/local/lib/python3.5/dist-packages/telebot/apihelper.py", line 60, in _make_request
    return _check_result(method_name, result)['result']
  File "/usr/local/lib/python3.5/dist-packages/telebot/apihelper.py", line 79, in _check_result
    raise ApiException(msg, method_name, result)
telebot.apihelper.ApiException: A request to the Telegram API was unsuccessful. The server returned HTTP 409 Conflict. Response body:
[b'{"ok":false,"error_code":409,"description":"Conflict: terminated by other getUpdates request; make sure that only one bot instance is running"}']
"
2020-05-06 16:53:02,710 (__init__.py:420 MainThread) ERROR - TeleBot: "A request to the Telegram API was unsuccessful. The server returned HTTP 409 Conflict. Response body:
[b'{"ok":false,"error_code":409,"description":"Conflict: terminated by other getUpdates request; make sure that only one bot instance is running"}']"
{"ok":false,"error_code":403,"description":"Forbidden: bot can't initiate conversation with a user"}2020-05-06 18:08:38,728 (util.py:66 WorkerThread1) ERROR - TeleBot: "FileNotFoundError occurred, args=(2, 'No such file or directory')
Traceback (most recent call last):
  File "/usr/local/lib/python3.5/dist-packages/telebot/util.py", line 60, in run
    task(*args, **kwargs)
  File "main.py", line 97, in random_sentence
    bot.send_message(m.chat.id, generate("history" + str(m.chat.id) + ".txt"))
  File "main.py", line 157, in generate
    file = open(filename, "r")
FileNotFoundError: [Errno 2] No such file or directory: 'history698945902.txt'
"
Traceback (most recent call last):
  File "main.py", line 200, in <module>
    bot.polling()
  File "/usr/local/lib/python3.5/dist-packages/telebot/__init__.py", line 392, in polling
    self.__threaded_polling(none_stop, interval, timeout)
  File "/usr/local/lib/python3.5/dist-packages/telebot/__init__.py", line 416, in __threaded_polling
    self.worker_pool.raise_exceptions()
  File "/usr/local/lib/python3.5/dist-packages/telebot/util.py", line 109, in raise_exceptions
    six.reraise(self.exc_info[0], self.exc_info[1], self.exc_info[2])
  File "/usr/lib/python3/dist-packages/six.py", line 686, in reraise
    raise value
  File "/usr/local/lib/python3.5/dist-packages/telebot/util.py", line 60, in run
    task(*args, **kwargs)
  File "main.py", line 97, in random_sentence
    bot.send_message(m.chat.id, generate("history" + str(m.chat.id) + ".txt"))
  File "main.py", line 157, in generate
    file = open(filename, "r")
FileNotFoundError: [Errno 2] No such file or directory: 'history698945902.txt'
2020-05-07 04:20:17,830 (util.py:66 WorkerThread1) ERROR - TeleBot: "FileNotFoundError occurred, args=(2, 'No such file or directory')
Traceback (most recent call last):
  File "/usr/local/lib/python3.5/dist-packages/telebot/util.py", line 60, in run
    task(*args, **kwargs)
  File "main.py", line 115, in command_history
    with open("history" + str(m.chat.id) + ".txt") as f:
FileNotFoundError: [Errno 2] No such file or directory: 'history698945902.txt'
"
Traceback (most recent call last):
  File "main.py", line 200, in <module>
    bot.polling()
  File "/usr/local/lib/python3.5/dist-packages/telebot/__init__.py", line 392, in polling
    self.__threaded_polling(none_stop, interval, timeout)
  File "/usr/local/lib/python3.5/dist-packages/telebot/__init__.py", line 416, in __threaded_polling
    self.worker_pool.raise_exceptions()
  File "/usr/local/lib/python3.5/dist-packages/telebot/util.py", line 109, in raise_exceptions
    six.reraise(self.exc_info[0], self.exc_info[1], self.exc_info[2])
  File "/usr/lib/python3/dist-packages/six.py", line 686, in reraise
    raise value
  File "/usr/local/lib/python3.5/dist-packages/telebot/util.py", line 60, in run
    task(*args, **kwargs)
  File "main.py", line 115, in command_history
    with open("history" + str(m.chat.id) + ".txt") as f:
FileNotFoundError: [Errno 2] No such file or directory: 'history698945902.txt'
{"ok":false,"error_code":403,"description":"Forbidden: bot can't initiate conversation with a user"}2020-05-07 17:14:00,101 (util.py:66 WorkerThread1) ERROR - TeleBot: "IndexError occurred, args=('list index out of range',)
Traceback (most recent call last):
  File "/usr/local/lib/python3.5/dist-packages/telebot/util.py", line 60, in run
    task(*args, **kwargs)
  File "main.py", line 97, in random_sentence
    bot.send_message(m.chat.id, generate("history" + str(m.chat.id) + ".txt"))
  File "main.py", line 174, in generate
    dictionary[BEGIN].add(x[0])
IndexError: list index out of range
"
Traceback (most recent call last):
  File "main.py", line 200, in <module>
    bot.polling()
  File "/usr/local/lib/python3.5/dist-packages/telebot/__init__.py", line 392, in polling
    self.__threaded_polling(none_stop, interval, timeout)
  File "/usr/local/lib/python3.5/dist-packages/telebot/__init__.py", line 416, in __threaded_polling
    self.worker_pool.raise_exceptions()
  File "/usr/local/lib/python3.5/dist-packages/telebot/util.py", line 109, in raise_exceptions
    six.reraise(self.exc_info[0], self.exc_info[1], self.exc_info[2])
  File "/usr/lib/python3/dist-packages/six.py", line 686, in reraise
    raise value
  File "/usr/local/lib/python3.5/dist-packages/telebot/util.py", line 60, in run
    task(*args, **kwargs)
  File "main.py", line 97, in random_sentence
    bot.send_message(m.chat.id, generate("history" + str(m.chat.id) + ".txt"))
  File "main.py", line 174, in generate
    dictionary[BEGIN].add(x[0])
IndexError: list index out of range
2020-05-07 17:14:43,313 (util.py:66 WorkerThread2) ERROR - TeleBot: "IndexError occurred, args=('list index out of range',)
Traceback (most recent call last):
  File "/usr/local/lib/python3.5/dist-packages/telebot/util.py", line 60, in run
    task(*args, **kwargs)
  File "main.py", line 97, in random_sentence
    bot.send_message(m.chat.id, generate("history" + str(m.chat.id) + ".txt"))
  File "main.py", line 174, in generate
    dictionary[BEGIN].add(x[0])
IndexError: list index out of range
"
Traceback (most recent call last):
  File "main.py", line 200, in <module>
    bot.polling()
  File "/usr/local/lib/python3.5/dist-packages/telebot/__init__.py", line 392, in polling
    self.__threaded_polling(none_stop, interval, timeout)
  File "/usr/local/lib/python3.5/dist-packages/telebot/__init__.py", line 416, in __threaded_polling
    self.worker_pool.raise_exceptions()
  File "/usr/local/lib/python3.5/dist-packages/telebot/util.py", line 109, in raise_exceptions
    six.reraise(self.exc_info[0], self.exc_info[1], self.exc_info[2])
  File "/usr/lib/python3/dist-packages/six.py", line 686, in reraise
    raise value
  File "/usr/local/lib/python3.5/dist-packages/telebot/util.py", line 60, in run
    task(*args, **kwargs)
  File "main.py", line 97, in random_sentence
    bot.send_message(m.chat.id, generate("history" + str(m.chat.id) + ".txt"))
  File "main.py", line 174, in generate
    dictionary[BEGIN].add(x[0])
IndexError: list index out of range
2020-05-07 17:30:41,781 (util.py:66 PollingThread) ERROR - TeleBot: "ApiException occurred, args=('A request to the Telegram API was unsuccessful. The server returned HTTP 409 Conflict. Response body:\n[b\'{"ok":false,"error_code":409,"description":"Conflict: terminated by other getUpdates request; make sure that only one bot instance is running"}\']',)
Traceback (most recent call last):
  File "/usr/local/lib/python3.5/dist-packages/telebot/util.py", line 60, in run
    task(*args, **kwargs)
  File "/usr/local/lib/python3.5/dist-packages/telebot/__init__.py", line 279, in __retrieve_updates
    updates = self.get_updates(offset=(self.last_update_id + 1), timeout=timeout)
  File "/usr/local/lib/python3.5/dist-packages/telebot/__init__.py", line 249, in get_updates
    json_updates = apihelper.get_updates(self.token, offset, limit, timeout, allowed_updates)
  File "/usr/local/lib/python3.5/dist-packages/telebot/apihelper.py", line 194, in get_updates
    return _make_request(token, method_url, params=payload)
  File "/usr/local/lib/python3.5/dist-packages/telebot/apihelper.py", line 60, in _make_request
    return _check_result(method_name, result)['result']
  File "/usr/local/lib/python3.5/dist-packages/telebot/apihelper.py", line 79, in _check_result
    raise ApiException(msg, method_name, result)
telebot.apihelper.ApiException: A request to the Telegram API was unsuccessful. The server returned HTTP 409 Conflict. Response body:
[b'{"ok":false,"error_code":409,"description":"Conflict: terminated by other getUpdates request; make sure that only one bot instance is running"}']
"
2020-05-07 17:30:41,782 (__init__.py:420 MainThread) ERROR - TeleBot: "A request to the Telegram API was unsuccessful. The server returned HTTP 409 Conflict. Response body:
[b'{"ok":false,"error_code":409,"description":"Conflict: terminated by other getUpdates request; make sure that only one bot instance is running"}']"
2020-05-07 17:34:18,107 (util.py:66 PollingThread) ERROR - TeleBot: "ApiException occurred, args=('A request to the Telegram API was unsuccessful. The server returned HTTP 409 Conflict. Response body:\n[b\'{"ok":false,"error_code":409,"description":"Conflict: terminated by other getUpdates request; make sure that only one bot instance is running"}\']',)
Traceback (most recent call last):
  File "/usr/local/lib/python3.5/dist-packages/telebot/util.py", line 60, in run
    task(*args, **kwargs)
  File "/usr/local/lib/python3.5/dist-packages/telebot/__init__.py", line 279, in __retrieve_updates
    updates = self.get_updates(offset=(self.last_update_id + 1), timeout=timeout)
  File "/usr/local/lib/python3.5/dist-packages/telebot/__init__.py", line 249, in get_updates
    json_updates = apihelper.get_updates(self.token, offset, limit, timeout, allowed_updates)
  File "/usr/local/lib/python3.5/dist-packages/telebot/apihelper.py", line 194, in get_updates
    return _make_request(token, method_url, params=payload)
  File "/usr/local/lib/python3.5/dist-packages/telebot/apihelper.py", line 60, in _make_request
    return _check_result(method_name, result)['result']
  File "/usr/local/lib/python3.5/dist-packages/telebot/apihelper.py", line 79, in _check_result
    raise ApiException(msg, method_name, result)
telebot.apihelper.ApiException: A request to the Telegram API was unsuccessful. The server returned HTTP 409 Conflict. Response body:
[b'{"ok":false,"error_code":409,"description":"Conflict: terminated by other getUpdates request; make sure that only one bot instance is running"}']
"
2020-05-07 17:34:18,107 (__init__.py:420 MainThread) ERROR - TeleBot: "A request to the Telegram API was unsuccessful. The server returned HTTP 409 Conflict. Response body:
[b'{"ok":false,"error_code":409,"description":"Conflict: terminated by other getUpdates request; make sure that only one bot instance is running"}']"
2020-05-07 17:34:53,700 (util.py:66 PollingThread) ERROR - TeleBot: "ApiException occurred, args=('A request to the Telegram API was unsuccessful. The server returned HTTP 409 Conflict. Response body:\n[b\'{"ok":false,"error_code":409,"description":"Conflict: terminated by other getUpdates request; make sure that only one bot instance is running"}\']',)
Traceback (most recent call last):
  File "/usr/local/lib/python3.5/dist-packages/telebot/util.py", line 60, in run
    task(*args, **kwargs)
  File "/usr/local/lib/python3.5/dist-packages/telebot/__init__.py", line 279, in __retrieve_updates
    updates = self.get_updates(offset=(self.last_update_id + 1), timeout=timeout)
  File "/usr/local/lib/python3.5/dist-packages/telebot/__init__.py", line 249, in get_updates
    json_updates = apihelper.get_updates(self.token, offset, limit, timeout, allowed_updates)
  File "/usr/local/lib/python3.5/dist-packages/telebot/apihelper.py", line 194, in get_updates
    return _make_request(token, method_url, params=payload)
  File "/usr/local/lib/python3.5/dist-packages/telebot/apihelper.py", line 60, in _make_request
    return _check_result(method_name, result)['result']
  File "/usr/local/lib/python3.5/dist-packages/telebot/apihelper.py", line 79, in _check_result
    raise ApiException(msg, method_name, result)
telebot.apihelper.ApiException: A request to the Telegram API was unsuccessful. The server returned HTTP 409 Conflict. Response body:
[b'{"ok":false,"error_code":409,"description":"Conflict: terminated by other getUpdates request; make sure that only one bot instance is running"}']
"
2020-05-07 17:34:53,700 (__init__.py:420 MainThread) ERROR - TeleBot: "A request to the Telegram API was unsuccessful. The server returned HTTP 409 Conflict. Response body:
[b'{"ok":false,"error_code":409,"description":"Conflict: terminated by other getUpdates request; make sure that only one bot instance is running"}']"
2020-05-08 00:01:24,104 (util.py:66 PollingThread) ERROR - TeleBot: "ApiException occurred, args=('A request to the Telegram API was unsuccessful. The server returned HTTP 500 Internal Server Error. Response body:\n[b\'{"ok":false,"error_code":500,"description":"Internal Server Error: restart"}\']',)
Traceback (most recent call last):
  File "/usr/local/lib/python3.5/dist-packages/telebot/util.py", line 60, in run
    task(*args, **kwargs)
  File "/usr/local/lib/python3.5/dist-packages/telebot/__init__.py", line 279, in __retrieve_updates
    updates = self.get_updates(offset=(self.last_update_id + 1), timeout=timeout)
  File "/usr/local/lib/python3.5/dist-packages/telebot/__init__.py", line 249, in get_updates
    json_updates = apihelper.get_updates(self.token, offset, limit, timeout, allowed_updates)
  File "/usr/local/lib/python3.5/dist-packages/telebot/apihelper.py", line 194, in get_updates
    return _make_request(token, method_url, params=payload)
  File "/usr/local/lib/python3.5/dist-packages/telebot/apihelper.py", line 60, in _make_request
    return _check_result(method_name, result)['result']
  File "/usr/local/lib/python3.5/dist-packages/telebot/apihelper.py", line 79, in _check_result
    raise ApiException(msg, method_name, result)
telebot.apihelper.ApiException: A request to the Telegram API was unsuccessful. The server returned HTTP 500 Internal Server Error. Response body:
[b'{"ok":false,"error_code":500,"description":"Internal Server Error: restart"}']
"
2020-05-08 00:01:24,105 (__init__.py:420 MainThread) ERROR - TeleBot: "A request to the Telegram API was unsuccessful. The server returned HTTP 500 Internal Server Error. Response body:
[b'{"ok":false,"error_code":500,"description":"Internal Server Error: restart"}']"
2020-05-08 12:07:13,011 (util.py:66 PollingThread) ERROR - TeleBot: "AttributeError occurred, args=("'NoneType' object has no attribute 'lower'",)
Traceback (most recent call last):
  File "/usr/local/lib/python3.5/dist-packages/telebot/util.py", line 60, in run
    task(*args, **kwargs)
  File "/usr/local/lib/python3.5/dist-packages/telebot/__init__.py", line 280, in __retrieve_updates
    self.process_new_updates(updates)
  File "/usr/local/lib/python3.5/dist-packages/telebot/__init__.py", line 317, in process_new_updates
    self.process_new_messages(new_messages)
  File "/usr/local/lib/python3.5/dist-packages/telebot/__init__.py", line 339, in process_new_messages
    self._notify_command_handlers(self.message_handlers, new_messages)
  File "/usr/local/lib/python3.5/dist-packages/telebot/__init__.py", line 1801, in _notify_command_handlers
    if self._test_message_handler(message_handler, message):
  File "/usr/local/lib/python3.5/dist-packages/telebot/__init__.py", line 1769, in _test_message_handler
    if not self._test_filter(filter, filter_value, message):
  File "/usr/local/lib/python3.5/dist-packages/telebot/__init__.py", line 1790, in _test_filter
    return test_cases.get(filter, lambda msg: False)(message)
  File "/usr/local/lib/python3.5/dist-packages/telebot/__init__.py", line 1787, in <lambda>
    'func': lambda msg: filter_value(msg)
  File "main.py", line 145, in <lambda>
    @bot.message_handler(func=lambda message: "сука" in message.text.lower())
AttributeError: 'NoneType' object has no attribute 'lower'
"
Traceback (most recent call last):
  File "main.py", line 202, in <module>
    bot.polling()
  File "/usr/local/lib/python3.5/dist-packages/telebot/__init__.py", line 392, in polling
    self.__threaded_polling(none_stop, interval, timeout)
  File "/usr/local/lib/python3.5/dist-packages/telebot/__init__.py", line 415, in __threaded_polling
    polling_thread.raise_exceptions()
  File "/usr/local/lib/python3.5/dist-packages/telebot/util.py", line 79, in raise_exceptions
    six.reraise(self.exc_info[0], self.exc_info[1], self.exc_info[2])
  File "/usr/lib/python3/dist-packages/six.py", line 686, in reraise
    raise value
  File "/usr/local/lib/python3.5/dist-packages/telebot/util.py", line 60, in run
    task(*args, **kwargs)
  File "/usr/local/lib/python3.5/dist-packages/telebot/__init__.py", line 280, in __retrieve_updates
    self.process_new_updates(updates)
  File "/usr/local/lib/python3.5/dist-packages/telebot/__init__.py", line 317, in process_new_updates
    self.process_new_messages(new_messages)
  File "/usr/local/lib/python3.5/dist-packages/telebot/__init__.py", line 339, in process_new_messages
    self._notify_command_handlers(self.message_handlers, new_messages)
  File "/usr/local/lib/python3.5/dist-packages/telebot/__init__.py", line 1801, in _notify_command_handlers
    if self._test_message_handler(message_handler, message):
  File "/usr/local/lib/python3.5/dist-packages/telebot/__init__.py", line 1769, in _test_message_handler
    if not self._test_filter(filter, filter_value, message):
  File "/usr/local/lib/python3.5/dist-packages/telebot/__init__.py", line 1790, in _test_filter
    return test_cases.get(filter, lambda msg: False)(message)
  File "/usr/local/lib/python3.5/dist-packages/telebot/__init__.py", line 1787, in <lambda>
    'func': lambda msg: filter_value(msg)
  File "main.py", line 145, in <lambda>
    @bot.message_handler(func=lambda message: "сука" in message.text.lower())
AttributeError: 'NoneType' object has no attribute 'lower'
{"ok":false,"error_code":403,"description":"Forbidden: bot can't initiate conversation with a user"}2020-05-12 15:55:42,804 (util.py:66 PollingThread) ERROR - TeleBot: "ApiException occurred, args=('A request to the Telegram API was unsuccessful. The server returned HTTP 409 Conflict. Response body:\n[b\'{"ok":false,"error_code":409,"description":"Conflict: terminated by other getUpdates request; make sure that only one bot instance is running"}\']',)
Traceback (most recent call last):
  File "/usr/local/lib/python3.5/dist-packages/telebot/util.py", line 60, in run
    task(*args, **kwargs)
  File "/usr/local/lib/python3.5/dist-packages/telebot/__init__.py", line 279, in __retrieve_updates
    updates = self.get_updates(offset=(self.last_update_id + 1), timeout=timeout)
  File "/usr/local/lib/python3.5/dist-packages/telebot/__init__.py", line 249, in get_updates
    json_updates = apihelper.get_updates(self.token, offset, limit, timeout, allowed_updates)
  File "/usr/local/lib/python3.5/dist-packages/telebot/apihelper.py", line 194, in get_updates
    return _make_request(token, method_url, params=payload)
  File "/usr/local/lib/python3.5/dist-packages/telebot/apihelper.py", line 60, in _make_request
    return _check_result(method_name, result)['result']
  File "/usr/local/lib/python3.5/dist-packages/telebot/apihelper.py", line 79, in _check_result
    raise ApiException(msg, method_name, result)
telebot.apihelper.ApiException: A request to the Telegram API was unsuccessful. The server returned HTTP 409 Conflict. Response body:
[b'{"ok":false,"error_code":409,"description":"Conflict: terminated by other getUpdates request; make sure that only one bot instance is running"}']
"
2020-05-12 15:55:42,805 (__init__.py:420 MainThread) ERROR - TeleBot: "A request to the Telegram API was unsuccessful. The server returned HTTP 409 Conflict. Response body:
[b'{"ok":false,"error_code":409,"description":"Conflict: terminated by other getUpdates request; make sure that only one bot instance is running"}']"
  File "main.py", line 107
    def random_sentence(m):
      ^
SyntaxError: invalid syntax
  File "main.py", line 107
    def random_sentence(m):
      ^
SyntaxError: invalid syntax
  File "main.py", line 107
    def rarge_random_sentence(m):
      ^
SyntaxError: invalid syntax
2020-05-17 05:37:13,566 (util.py:66 PollingThread) ERROR - TeleBot: "ApiException occurred, args=('A request to the Telegram API was unsuccessful. The server returned HTTP 409 Conflict. Response body:\n[b\'{"ok":false,"error_code":409,"description":"Conflict: terminated by other getUpdates request; make sure that only one bot instance is running"}\']',)
Traceback (most recent call last):
  File "/usr/local/lib/python3.5/dist-packages/telebot/util.py", line 60, in run
    task(*args, **kwargs)
  File "/usr/local/lib/python3.5/dist-packages/telebot/__init__.py", line 279, in __retrieve_updates
    updates = self.get_updates(offset=(self.last_update_id + 1), timeout=timeout)
  File "/usr/local/lib/python3.5/dist-packages/telebot/__init__.py", line 249, in get_updates
    json_updates = apihelper.get_updates(self.token, offset, limit, timeout, allowed_updates)
  File "/usr/local/lib/python3.5/dist-packages/telebot/apihelper.py", line 194, in get_updates
    return _make_request(token, method_url, params=payload)
  File "/usr/local/lib/python3.5/dist-packages/telebot/apihelper.py", line 60, in _make_request
    return _check_result(method_name, result)['result']
  File "/usr/local/lib/python3.5/dist-packages/telebot/apihelper.py", line 79, in _check_result
    raise ApiException(msg, method_name, result)
telebot.apihelper.ApiException: A request to the Telegram API was unsuccessful. The server returned HTTP 409 Conflict. Response body:
[b'{"ok":false,"error_code":409,"description":"Conflict: terminated by other getUpdates request; make sure that only one bot instance is running"}']
"
2020-05-17 05:37:13,566 (__init__.py:420 MainThread) ERROR - TeleBot: "A request to the Telegram API was unsuccessful. The server returned HTTP 409 Conflict. Response body:
[b'{"ok":false,"error_code":409,"description":"Conflict: terminated by other getUpdates request; make sure that only one bot instance is running"}']"
2020-05-17 05:38:16,107 (util.py:66 PollingThread) ERROR - TeleBot: "ApiException occurred, args=('A request to the Telegram API was unsuccessful. The server returned HTTP 409 Conflict. Response body:\n[b\'{"ok":false,"error_code":409,"description":"Conflict: terminated by other getUpdates request; make sure that only one bot instance is running"}\']',)
Traceback (most recent call last):
  File "/usr/local/lib/python3.5/dist-packages/telebot/util.py", line 60, in run
    task(*args, **kwargs)
  File "/usr/local/lib/python3.5/dist-packages/telebot/__init__.py", line 279, in __retrieve_updates
    updates = self.get_updates(offset=(self.last_update_id + 1), timeout=timeout)
  File "/usr/local/lib/python3.5/dist-packages/telebot/__init__.py", line 249, in get_updates
    json_updates = apihelper.get_updates(self.token, offset, limit, timeout, allowed_updates)
  File "/usr/local/lib/python3.5/dist-packages/telebot/apihelper.py", line 194, in get_updates
    return _make_request(token, method_url, params=payload)
  File "/usr/local/lib/python3.5/dist-packages/telebot/apihelper.py", line 60, in _make_request
    return _check_result(method_name, result)['result']
  File "/usr/local/lib/python3.5/dist-packages/telebot/apihelper.py", line 79, in _check_result
    raise ApiException(msg, method_name, result)
telebot.apihelper.ApiException: A request to the Telegram API was unsuccessful. The server returned HTTP 409 Conflict. Response body:
[b'{"ok":false,"error_code":409,"description":"Conflict: terminated by other getUpdates request; make sure that only one bot instance is running"}']
"
2020-05-17 05:38:16,107 (__init__.py:420 MainThread) ERROR - TeleBot: "A request to the Telegram API was unsuccessful. The server returned HTTP 409 Conflict. Response body:
[b'{"ok":false,"error_code":409,"description":"Conflict: terminated by other getUpdates request; make sure that only one bot instance is running"}']"
2020-05-17 05:39:15,453 (util.py:66 PollingThread) ERROR - TeleBot: "ApiException occurred, args=('A request to the Telegram API was unsuccessful. The server returned HTTP 409 Conflict. Response body:\n[b\'{"ok":false,"error_code":409,"description":"Conflict: terminated by other getUpdates request; make sure that only one bot instance is running"}\']',)
Traceback (most recent call last):
  File "/usr/local/lib/python3.5/dist-packages/telebot/util.py", line 60, in run
    task(*args, **kwargs)
  File "/usr/local/lib/python3.5/dist-packages/telebot/__init__.py", line 279, in __retrieve_updates
    updates = self.get_updates(offset=(self.last_update_id + 1), timeout=timeout)
  File "/usr/local/lib/python3.5/dist-packages/telebot/__init__.py", line 249, in get_updates
    json_updates = apihelper.get_updates(self.token, offset, limit, timeout, allowed_updates)
  File "/usr/local/lib/python3.5/dist-packages/telebot/apihelper.py", line 194, in get_updates
    return _make_request(token, method_url, params=payload)
  File "/usr/local/lib/python3.5/dist-packages/telebot/apihelper.py", line 60, in _make_request
    return _check_result(method_name, result)['result']
  File "/usr/local/lib/python3.5/dist-packages/telebot/apihelper.py", line 79, in _check_result
    raise ApiException(msg, method_name, result)
telebot.apihelper.ApiException: A request to the Telegram API was unsuccessful. The server returned HTTP 409 Conflict. Response body:
[b'{"ok":false,"error_code":409,"description":"Conflict: terminated by other getUpdates request; make sure that only one bot instance is running"}']
"
2020-05-17 05:39:15,454 (__init__.py:420 MainThread) ERROR - TeleBot: "A request to the Telegram API was unsuccessful. The server returned HTTP 409 Conflict. Response body:
[b'{"ok":false,"error_code":409,"description":"Conflict: terminated by other getUpdates request; make sure that only one bot instance is running"}']"
2020-05-17 05:41:14,669 (util.py:66 PollingThread) ERROR - TeleBot: "ApiException occurred, args=('A request to the Telegram API was unsuccessful. The server returned HTTP 409 Conflict. Response body:\n[b\'{"ok":false,"error_code":409,"description":"Conflict: terminated by other getUpdates request; make sure that only one bot instance is running"}\']',)
Traceback (most recent call last):
  File "/usr/local/lib/python3.5/dist-packages/telebot/util.py", line 60, in run
    task(*args, **kwargs)
  File "/usr/local/lib/python3.5/dist-packages/telebot/__init__.py", line 279, in __retrieve_updates
    updates = self.get_updates(offset=(self.last_update_id + 1), timeout=timeout)
  File "/usr/local/lib/python3.5/dist-packages/telebot/__init__.py", line 249, in get_updates
    json_updates = apihelper.get_updates(self.token, offset, limit, timeout, allowed_updates)
  File "/usr/local/lib/python3.5/dist-packages/telebot/apihelper.py", line 194, in get_updates
    return _make_request(token, method_url, params=payload)
  File "/usr/local/lib/python3.5/dist-packages/telebot/apihelper.py", line 60, in _make_request
    return _check_result(method_name, result)['result']
  File "/usr/local/lib/python3.5/dist-packages/telebot/apihelper.py", line 79, in _check_result
    raise ApiException(msg, method_name, result)
telebot.apihelper.ApiException: A request to the Telegram API was unsuccessful. The server returned HTTP 409 Conflict. Response body:
[b'{"ok":false,"error_code":409,"description":"Conflict: terminated by other getUpdates request; make sure that only one bot instance is running"}']
"
2020-05-17 05:41:14,670 (__init__.py:420 MainThread) ERROR - TeleBot: "A request to the Telegram API was unsuccessful. The server returned HTTP 409 Conflict. Response body:
[b'{"ok":false,"error_code":409,"description":"Conflict: terminated by other getUpdates request; make sure that only one bot instance is running"}']"
2020-05-17 05:46:40,198 (util.py:66 PollingThread) ERROR - TeleBot: "ApiException occurred, args=('A request to the Telegram API was unsuccessful. The server returned HTTP 409 Conflict. Response body:\n[b\'{"ok":false,"error_code":409,"description":"Conflict: terminated by other getUpdates request; make sure that only one bot instance is running"}\']',)
Traceback (most recent call last):
  File "/usr/local/lib/python3.5/dist-packages/telebot/util.py", line 60, in run
    task(*args, **kwargs)
  File "/usr/local/lib/python3.5/dist-packages/telebot/__init__.py", line 279, in __retrieve_updates
    updates = self.get_updates(offset=(self.last_update_id + 1), timeout=timeout)
  File "/usr/local/lib/python3.5/dist-packages/telebot/__init__.py", line 249, in get_updates
    json_updates = apihelper.get_updates(self.token, offset, limit, timeout, allowed_updates)
  File "/usr/local/lib/python3.5/dist-packages/telebot/apihelper.py", line 194, in get_updates
    return _make_request(token, method_url, params=payload)
  File "/usr/local/lib/python3.5/dist-packages/telebot/apihelper.py", line 60, in _make_request
    return _check_result(method_name, result)['result']
  File "/usr/local/lib/python3.5/dist-packages/telebot/apihelper.py", line 79, in _check_result
    raise ApiException(msg, method_name, result)
telebot.apihelper.ApiException: A request to the Telegram API was unsuccessful. The server returned HTTP 409 Conflict. Response body:
[b'{"ok":false,"error_code":409,"description":"Conflict: terminated by other getUpdates request; make sure that only one bot instance is running"}']
"
2020-05-17 05:46:40,199 (__init__.py:420 MainThread) ERROR - TeleBot: "A request to the Telegram API was unsuccessful. The server returned HTTP 409 Conflict. Response body:
[b'{"ok":false,"error_code":409,"description":"Conflict: terminated by other getUpdates request; make sure that only one bot instance is running"}']"
2020-05-17 05:54:26,954 (util.py:66 PollingThread) ERROR - TeleBot: "ApiException occurred, args=('A request to the Telegram API was unsuccessful. The server returned HTTP 409 Conflict. Response body:\n[b\'{"ok":false,"error_code":409,"description":"Conflict: terminated by other getUpdates request; make sure that only one bot instance is running"}\']',)
Traceback (most recent call last):
  File "/usr/local/lib/python3.5/dist-packages/telebot/util.py", line 60, in run
    task(*args, **kwargs)
  File "/usr/local/lib/python3.5/dist-packages/telebot/__init__.py", line 279, in __retrieve_updates
    updates = self.get_updates(offset=(self.last_update_id + 1), timeout=timeout)
  File "/usr/local/lib/python3.5/dist-packages/telebot/__init__.py", line 249, in get_updates
    json_updates = apihelper.get_updates(self.token, offset, limit, timeout, allowed_updates)
  File "/usr/local/lib/python3.5/dist-packages/telebot/apihelper.py", line 194, in get_updates
    return _make_request(token, method_url, params=payload)
  File "/usr/local/lib/python3.5/dist-packages/telebot/apihelper.py", line 60, in _make_request
    return _check_result(method_name, result)['result']
  File "/usr/local/lib/python3.5/dist-packages/telebot/apihelper.py", line 79, in _check_result
    raise ApiException(msg, method_name, result)
telebot.apihelper.ApiException: A request to the Telegram API was unsuccessful. The server returned HTTP 409 Conflict. Response body:
[b'{"ok":false,"error_code":409,"description":"Conflict: terminated by other getUpdates request; make sure that only one bot instance is running"}']
"
2020-05-17 05:54:26,955 (__init__.py:420 MainThread) ERROR - TeleBot: "A request to the Telegram API was unsuccessful. The server returned HTTP 409 Conflict. Response body:
[b'{"ok":false,"error_code":409,"description":"Conflict: terminated by other getUpdates request; make sure that only one bot instance is running"}']"
2020-05-17 06:07:55,108 (util.py:66 PollingThread) ERROR - TeleBot: "AttributeError occurred, args=("'NoneType' object has no attribute 'lower'",)
Traceback (most recent call last):
  File "/usr/local/lib/python3.5/dist-packages/telebot/util.py", line 60, in run
    task(*args, **kwargs)
  File "/usr/local/lib/python3.5/dist-packages/telebot/__init__.py", line 280, in __retrieve_updates
    self.process_new_updates(updates)
  File "/usr/local/lib/python3.5/dist-packages/telebot/__init__.py", line 317, in process_new_updates
    self.process_new_messages(new_messages)
  File "/usr/local/lib/python3.5/dist-packages/telebot/__init__.py", line 339, in process_new_messages
    self._notify_command_handlers(self.message_handlers, new_messages)
  File "/usr/local/lib/python3.5/dist-packages/telebot/__init__.py", line 1801, in _notify_command_handlers
    if self._test_message_handler(message_handler, message):
  File "/usr/local/lib/python3.5/dist-packages/telebot/__init__.py", line 1769, in _test_message_handler
    if not self._test_filter(filter, filter_value, message):
  File "/usr/local/lib/python3.5/dist-packages/telebot/__init__.py", line 1790, in _test_filter
    return test_cases.get(filter, lambda msg: False)(message)
  File "/usr/local/lib/python3.5/dist-packages/telebot/__init__.py", line 1787, in <lambda>
    'func': lambda msg: filter_value(msg)
  File "main.py", line 173, in <lambda>
    @bot.message_handler(func=lambda message: "сука" in message.text.lower())
AttributeError: 'NoneType' object has no attribute 'lower'
"
Traceback (most recent call last):
  File "main.py", line 232, in <module>
    bot.polling()
  File "/usr/local/lib/python3.5/dist-packages/telebot/__init__.py", line 392, in polling
    self.__threaded_polling(none_stop, interval, timeout)
  File "/usr/local/lib/python3.5/dist-packages/telebot/__init__.py", line 415, in __threaded_polling
    polling_thread.raise_exceptions()
  File "/usr/local/lib/python3.5/dist-packages/telebot/util.py", line 79, in raise_exceptions
    six.reraise(self.exc_info[0], self.exc_info[1], self.exc_info[2])
  File "/usr/lib/python3/dist-packages/six.py", line 686, in reraise
    raise value
  File "/usr/local/lib/python3.5/dist-packages/telebot/util.py", line 60, in run
    task(*args, **kwargs)
  File "/usr/local/lib/python3.5/dist-packages/telebot/__init__.py", line 280, in __retrieve_updates
    self.process_new_updates(updates)
  File "/usr/local/lib/python3.5/dist-packages/telebot/__init__.py", line 317, in process_new_updates
    self.process_new_messages(new_messages)
  File "/usr/local/lib/python3.5/dist-packages/telebot/__init__.py", line 339, in process_new_messages
    self._notify_command_handlers(self.message_handlers, new_messages)
  File "/usr/local/lib/python3.5/dist-packages/telebot/__init__.py", line 1801, in _notify_command_handlers
    if self._test_message_handler(message_handler, message):
  File "/usr/local/lib/python3.5/dist-packages/telebot/__init__.py", line 1769, in _test_message_handler
    if not self._test_filter(filter, filter_value, message):
  File "/usr/local/lib/python3.5/dist-packages/telebot/__init__.py", line 1790, in _test_filter
    return test_cases.get(filter, lambda msg: False)(message)
  File "/usr/local/lib/python3.5/dist-packages/telebot/__init__.py", line 1787, in <lambda>
    'func': lambda msg: filter_value(msg)
  File "main.py", line 173, in <lambda>
    @bot.message_handler(func=lambda message: "сука" in message.text.lower())
AttributeError: 'NoneType' object has no attribute 'lower'
2020-05-23 00:27:32,052 (util.py:66 PollingThread) ERROR - TeleBot: "ApiException occurred, args=('A request to the Telegram API was unsuccessful. The server returned HTTP 500 Internal Server Error. Response body:\n[b\'{"ok":false,"error_code":500,"description":"Internal Server Error: restart"}\']',)
Traceback (most recent call last):
  File "/usr/local/lib/python3.5/dist-packages/telebot/util.py", line 60, in run
    task(*args, **kwargs)
  File "/usr/local/lib/python3.5/dist-packages/telebot/__init__.py", line 279, in __retrieve_updates
    updates = self.get_updates(offset=(self.last_update_id + 1), timeout=timeout)
  File "/usr/local/lib/python3.5/dist-packages/telebot/__init__.py", line 249, in get_updates
    json_updates = apihelper.get_updates(self.token, offset, limit, timeout, allowed_updates)
  File "/usr/local/lib/python3.5/dist-packages/telebot/apihelper.py", line 194, in get_updates
    return _make_request(token, method_url, params=payload)
  File "/usr/local/lib/python3.5/dist-packages/telebot/apihelper.py", line 60, in _make_request
    return _check_result(method_name, result)['result']
  File "/usr/local/lib/python3.5/dist-packages/telebot/apihelper.py", line 79, in _check_result
    raise ApiException(msg, method_name, result)
telebot.apihelper.ApiException: A request to the Telegram API was unsuccessful. The server returned HTTP 500 Internal Server Error. Response body:
[b'{"ok":false,"error_code":500,"description":"Internal Server Error: restart"}']
"
2020-05-23 00:27:32,052 (__init__.py:420 MainThread) ERROR - TeleBot: "A request to the Telegram API was unsuccessful. The server returned HTTP 500 Internal Server Error. Response body:
[b'{"ok":false,"error_code":500,"description":"Internal Server Error: restart"}']"
2020-05-24 16:50:44,726 (util.py:66 WorkerThread1) ERROR - TeleBot: "TypeError occurred, args=("argument of type 'NoneType' is not iterable",)
Traceback (most recent call last):
  File "/usr/local/lib/python3.5/dist-packages/telebot/util.py", line 60, in run
    task(*args, **kwargs)
  File "main.py", line 75, in listener
    if "бот насколько " in m.text or "насколько" in m.text:
TypeError: argument of type 'NoneType' is not iterable
"
Traceback (most recent call last):
  File "main.py", line 241, in <module>
    bot.polling()
  File "/usr/local/lib/python3.5/dist-packages/telebot/__init__.py", line 392, in polling
    self.__threaded_polling(none_stop, interval, timeout)
  File "/usr/local/lib/python3.5/dist-packages/telebot/__init__.py", line 416, in __threaded_polling
    self.worker_pool.raise_exceptions()
  File "/usr/local/lib/python3.5/dist-packages/telebot/util.py", line 109, in raise_exceptions
    six.reraise(self.exc_info[0], self.exc_info[1], self.exc_info[2])
  File "/usr/lib/python3/dist-packages/six.py", line 686, in reraise
    raise value
  File "/usr/local/lib/python3.5/dist-packages/telebot/util.py", line 60, in run
    task(*args, **kwargs)
  File "main.py", line 75, in listener
    if "бот насколько " in m.text or "насколько" in m.text:
TypeError: argument of type 'NoneType' is not iterable
2020-05-24 17:07:43,640 (util.py:66 WorkerThread2) ERROR - TeleBot: "TypeError occurred, args=("argument of type 'NoneType' is not iterable",)
Traceback (most recent call last):
  File "/usr/local/lib/python3.5/dist-packages/telebot/util.py", line 60, in run
    task(*args, **kwargs)
  File "main.py", line 75, in listener
    if "бот насколько " in m.text or "насколько" in m.text:
TypeError: argument of type 'NoneType' is not iterable
"
Traceback (most recent call last):
  File "main.py", line 241, in <module>
    bot.polling()
  File "/usr/local/lib/python3.5/dist-packages/telebot/__init__.py", line 392, in polling
    self.__threaded_polling(none_stop, interval, timeout)
  File "/usr/local/lib/python3.5/dist-packages/telebot/__init__.py", line 416, in __threaded_polling
    self.worker_pool.raise_exceptions()
  File "/usr/local/lib/python3.5/dist-packages/telebot/util.py", line 109, in raise_exceptions
    six.reraise(self.exc_info[0], self.exc_info[1], self.exc_info[2])
  File "/usr/lib/python3/dist-packages/six.py", line 686, in reraise
    raise value
  File "/usr/local/lib/python3.5/dist-packages/telebot/util.py", line 60, in run
    task(*args, **kwargs)
  File "main.py", line 75, in listener
    if "бот насколько " in m.text or "насколько" in m.text:
TypeError: argument of type 'NoneType' is not iterable
2020-05-24 17:08:52,141 (util.py:66 WorkerThread1) ERROR - TeleBot: "TypeError occurred, args=("argument of type 'NoneType' is not iterable",)
Traceback (most recent call last):
  File "/usr/local/lib/python3.5/dist-packages/telebot/util.py", line 60, in run
    task(*args, **kwargs)
  File "main.py", line 75, in listener
    if "бот насколько " in m.text or "насколько" in m.text:
TypeError: argument of type 'NoneType' is not iterable
"
Traceback (most recent call last):
  File "main.py", line 241, in <module>
    bot.polling()
  File "/usr/local/lib/python3.5/dist-packages/telebot/__init__.py", line 392, in polling
    self.__threaded_polling(none_stop, interval, timeout)
  File "/usr/local/lib/python3.5/dist-packages/telebot/__init__.py", line 416, in __threaded_polling
    self.worker_pool.raise_exceptions()
  File "/usr/local/lib/python3.5/dist-packages/telebot/util.py", line 109, in raise_exceptions
    six.reraise(self.exc_info[0], self.exc_info[1], self.exc_info[2])
  File "/usr/lib/python3/dist-packages/six.py", line 686, in reraise
    raise value
  File "/usr/local/lib/python3.5/dist-packages/telebot/util.py", line 60, in run
    task(*args, **kwargs)
  File "main.py", line 75, in listener
    if "бот насколько " in m.text or "насколько" in m.text:
TypeError: argument of type 'NoneType' is not iterable
2020-05-24 17:08:56,989 (util.py:66 WorkerThread1) ERROR - TeleBot: "TypeError occurred, args=("argument of type 'NoneType' is not iterable",)
Traceback (most recent call last):
  File "/usr/local/lib/python3.5/dist-packages/telebot/util.py", line 60, in run
    task(*args, **kwargs)
  File "main.py", line 75, in listener
    if "бот насколько " in m.text or "насколько" in m.text:
TypeError: argument of type 'NoneType' is not iterable
"
Traceback (most recent call last):
  File "main.py", line 241, in <module>
    bot.polling()
  File "/usr/local/lib/python3.5/dist-packages/telebot/__init__.py", line 392, in polling
    self.__threaded_polling(none_stop, interval, timeout)
  File "/usr/local/lib/python3.5/dist-packages/telebot/__init__.py", line 416, in __threaded_polling
    self.worker_pool.raise_exceptions()
  File "/usr/local/lib/python3.5/dist-packages/telebot/util.py", line 109, in raise_exceptions
    six.reraise(self.exc_info[0], self.exc_info[1], self.exc_info[2])
  File "/usr/lib/python3/dist-packages/six.py", line 686, in reraise
    raise value
  File "/usr/local/lib/python3.5/dist-packages/telebot/util.py", line 60, in run
    task(*args, **kwargs)
  File "main.py", line 75, in listener
    if "бот насколько " in m.text or "насколько" in m.text:
TypeError: argument of type 'NoneType' is not iterable
2020-05-24 17:16:50,265 (util.py:66 PollingThread) ERROR - TeleBot: "ApiException occurred, args=('A request to the Telegram API was unsuccessful. The server returned HTTP 409 Conflict. Response body:\n[b\'{"ok":false,"error_code":409,"description":"Conflict: terminated by other getUpdates request; make sure that only one bot instance is running"}\']',)
Traceback (most recent call last):
  File "/usr/local/lib/python3.5/dist-packages/telebot/util.py", line 60, in run
    task(*args, **kwargs)
  File "/usr/local/lib/python3.5/dist-packages/telebot/__init__.py", line 279, in __retrieve_updates
    updates = self.get_updates(offset=(self.last_update_id + 1), timeout=timeout)
  File "/usr/local/lib/python3.5/dist-packages/telebot/__init__.py", line 249, in get_updates
    json_updates = apihelper.get_updates(self.token, offset, limit, timeout, allowed_updates)
  File "/usr/local/lib/python3.5/dist-packages/telebot/apihelper.py", line 194, in get_updates
    return _make_request(token, method_url, params=payload)
  File "/usr/local/lib/python3.5/dist-packages/telebot/apihelper.py", line 60, in _make_request
    return _check_result(method_name, result)['result']
  File "/usr/local/lib/python3.5/dist-packages/telebot/apihelper.py", line 79, in _check_result
    raise ApiException(msg, method_name, result)
telebot.apihelper.ApiException: A request to the Telegram API was unsuccessful. The server returned HTTP 409 Conflict. Response body:
[b'{"ok":false,"error_code":409,"description":"Conflict: terminated by other getUpdates request; make sure that only one bot instance is running"}']
"
2020-05-24 17:16:50,266 (__init__.py:420 MainThread) ERROR - TeleBot: "A request to the Telegram API was unsuccessful. The server returned HTTP 409 Conflict. Response body:
[b'{"ok":false,"error_code":409,"description":"Conflict: terminated by other getUpdates request; make sure that only one bot instance is running"}']"
2020-05-24 17:19:55,185 (util.py:66 PollingThread) ERROR - TeleBot: "ApiException occurred, args=('A request to the Telegram API was unsuccessful. The server returned HTTP 409 Conflict. Response body:\n[b\'{"ok":false,"error_code":409,"description":"Conflict: terminated by other getUpdates request; make sure that only one bot instance is running"}\']',)
Traceback (most recent call last):
  File "/usr/local/lib/python3.5/dist-packages/telebot/util.py", line 60, in run
    task(*args, **kwargs)
  File "/usr/local/lib/python3.5/dist-packages/telebot/__init__.py", line 279, in __retrieve_updates
    updates = self.get_updates(offset=(self.last_update_id + 1), timeout=timeout)
  File "/usr/local/lib/python3.5/dist-packages/telebot/__init__.py", line 249, in get_updates
    json_updates = apihelper.get_updates(self.token, offset, limit, timeout, allowed_updates)
  File "/usr/local/lib/python3.5/dist-packages/telebot/apihelper.py", line 194, in get_updates
    return _make_request(token, method_url, params=payload)
  File "/usr/local/lib/python3.5/dist-packages/telebot/apihelper.py", line 60, in _make_request
    return _check_result(method_name, result)['result']
  File "/usr/local/lib/python3.5/dist-packages/telebot/apihelper.py", line 79, in _check_result
    raise ApiException(msg, method_name, result)
telebot.apihelper.ApiException: A request to the Telegram API was unsuccessful. The server returned HTTP 409 Conflict. Response body:
[b'{"ok":false,"error_code":409,"description":"Conflict: terminated by other getUpdates request; make sure that only one bot instance is running"}']
"
2020-05-24 17:19:55,185 (__init__.py:420 MainThread) ERROR - TeleBot: "A request to the Telegram API was unsuccessful. The server returned HTTP 409 Conflict. Response body:
[b'{"ok":false,"error_code":409,"description":"Conflict: terminated by other getUpdates request; make sure that only one bot instance is running"}']"
2020-05-24 17:27:33,096 (util.py:66 PollingThread) ERROR - TeleBot: "ApiException occurred, args=('A request to the Telegram API was unsuccessful. The server returned HTTP 409 Conflict. Response body:\n[b\'{"ok":false,"error_code":409,"description":"Conflict: terminated by other getUpdates request; make sure that only one bot instance is running"}\']',)
Traceback (most recent call last):
  File "/usr/local/lib/python3.5/dist-packages/telebot/util.py", line 60, in run
    task(*args, **kwargs)
  File "/usr/local/lib/python3.5/dist-packages/telebot/__init__.py", line 279, in __retrieve_updates
    updates = self.get_updates(offset=(self.last_update_id + 1), timeout=timeout)
  File "/usr/local/lib/python3.5/dist-packages/telebot/__init__.py", line 249, in get_updates
    json_updates = apihelper.get_updates(self.token, offset, limit, timeout, allowed_updates)
  File "/usr/local/lib/python3.5/dist-packages/telebot/apihelper.py", line 194, in get_updates
    return _make_request(token, method_url, params=payload)
  File "/usr/local/lib/python3.5/dist-packages/telebot/apihelper.py", line 60, in _make_request
    return _check_result(method_name, result)['result']
  File "/usr/local/lib/python3.5/dist-packages/telebot/apihelper.py", line 79, in _check_result
    raise ApiException(msg, method_name, result)
telebot.apihelper.ApiException: A request to the Telegram API was unsuccessful. The server returned HTTP 409 Conflict. Response body:
[b'{"ok":false,"error_code":409,"description":"Conflict: terminated by other getUpdates request; make sure that only one bot instance is running"}']
"
2020-05-24 17:27:33,097 (__init__.py:420 MainThread) ERROR - TeleBot: "A request to the Telegram API was unsuccessful. The server returned HTTP 409 Conflict. Response body:
[b'{"ok":false,"error_code":409,"description":"Conflict: terminated by other getUpdates request; make sure that only one bot instance is running"}']"
2020-05-24 17:34:16,639 (util.py:66 PollingThread) ERROR - TeleBot: "ApiException occurred, args=('A request to the Telegram API was unsuccessful. The server returned HTTP 409 Conflict. Response body:\n[b\'{"ok":false,"error_code":409,"description":"Conflict: terminated by other getUpdates request; make sure that only one bot instance is running"}\']',)
Traceback (most recent call last):
  File "/usr/local/lib/python3.5/dist-packages/telebot/util.py", line 60, in run
    task(*args, **kwargs)
  File "/usr/local/lib/python3.5/dist-packages/telebot/__init__.py", line 279, in __retrieve_updates
    updates = self.get_updates(offset=(self.last_update_id + 1), timeout=timeout)
  File "/usr/local/lib/python3.5/dist-packages/telebot/__init__.py", line 249, in get_updates
    json_updates = apihelper.get_updates(self.token, offset, limit, timeout, allowed_updates)
  File "/usr/local/lib/python3.5/dist-packages/telebot/apihelper.py", line 194, in get_updates
    return _make_request(token, method_url, params=payload)
  File "/usr/local/lib/python3.5/dist-packages/telebot/apihelper.py", line 60, in _make_request
    return _check_result(method_name, result)['result']
  File "/usr/local/lib/python3.5/dist-packages/telebot/apihelper.py", line 79, in _check_result
    raise ApiException(msg, method_name, result)
telebot.apihelper.ApiException: A request to the Telegram API was unsuccessful. The server returned HTTP 409 Conflict. Response body:
[b'{"ok":false,"error_code":409,"description":"Conflict: terminated by other getUpdates request; make sure that only one bot instance is running"}']
"
2020-05-24 17:34:16,640 (__init__.py:420 MainThread) ERROR - TeleBot: "A request to the Telegram API was unsuccessful. The server returned HTTP 409 Conflict. Response body:
[b'{"ok":false,"error_code":409,"description":"Conflict: terminated by other getUpdates request; make sure that only one bot instance is running"}']"
2020-05-25 15:33:58,510 (util.py:66 WorkerThread2) ERROR - TeleBot: "ApiException occurred, args=('A request to the Telegram API was unsuccessful. The server returned HTTP 429 Too Many Requests. Response body:\n[b\'{"ok":false,"error_code":429,"description":"Too Many Requests: retry after 9","parameters":{"retry_after":9}}\']',)
Traceback (most recent call last):
  File "/usr/local/lib/python3.5/dist-packages/telebot/util.py", line 60, in run
    task(*args, **kwargs)
  File "main.py", line 148, in small_random_sentence
    bot.send_message(m.chat.id, generate("history" + str(m.chat.id) + ".txt", SMALL))
  File "/usr/local/lib/python3.5/dist-packages/telebot/__init__.py", line 601, in send_message
    reply_markup, parse_mode, disable_notification, timeout))
  File "/usr/local/lib/python3.5/dist-packages/telebot/apihelper.py", line 154, in send_message
    return _make_request(token, method_url, params=payload, method='post')
  File "/usr/local/lib/python3.5/dist-packages/telebot/apihelper.py", line 60, in _make_request
    return _check_result(method_name, result)['result']
  File "/usr/local/lib/python3.5/dist-packages/telebot/apihelper.py", line 79, in _check_result
    raise ApiException(msg, method_name, result)
telebot.apihelper.ApiException: A request to the Telegram API was unsuccessful. The server returned HTTP 429 Too Many Requests. Response body:
[b'{"ok":false,"error_code":429,"description":"Too Many Requests: retry after 9","parameters":{"retry_after":9}}']
"
2020-05-25 15:33:58,510 (__init__.py:420 MainThread) ERROR - TeleBot: "A request to the Telegram API was unsuccessful. The server returned HTTP 429 Too Many Requests. Response body:
[b'{"ok":false,"error_code":429,"description":"Too Many Requests: retry after 9","parameters":{"retry_after":9}}']"
2020-05-25 15:35:39,841 (util.py:66 WorkerThread1) ERROR - TeleBot: "ApiException occurred, args=('A request to the Telegram API was unsuccessful. The server returned HTTP 429 Too Many Requests. Response body:\n[b\'{"ok":false,"error_code":429,"description":"Too Many Requests: retry after 37","parameters":{"retry_after":37}}\']',)
Traceback (most recent call last):
  File "/usr/local/lib/python3.5/dist-packages/telebot/util.py", line 60, in run
    task(*args, **kwargs)
  File "main.py", line 148, in small_random_sentence
    bot.send_message(m.chat.id, generate("history" + str(m.chat.id) + ".txt", SMALL))
  File "/usr/local/lib/python3.5/dist-packages/telebot/__init__.py", line 601, in send_message
    reply_markup, parse_mode, disable_notification, timeout))
  File "/usr/local/lib/python3.5/dist-packages/telebot/apihelper.py", line 154, in send_message
    return _make_request(token, method_url, params=payload, method='post')
  File "/usr/local/lib/python3.5/dist-packages/telebot/apihelper.py", line 60, in _make_request
    return _check_result(method_name, result)['result']
  File "/usr/local/lib/python3.5/dist-packages/telebot/apihelper.py", line 79, in _check_result
    raise ApiException(msg, method_name, result)
telebot.apihelper.ApiException: A request to the Telegram API was unsuccessful. The server returned HTTP 429 Too Many Requests. Response body:
[b'{"ok":false,"error_code":429,"description":"Too Many Requests: retry after 37","parameters":{"retry_after":37}}']
"
2020-05-25 15:35:39,841 (__init__.py:420 MainThread) ERROR - TeleBot: "A request to the Telegram API was unsuccessful. The server returned HTTP 429 Too Many Requests. Response body:
[b'{"ok":false,"error_code":429,"description":"Too Many Requests: retry after 37","parameters":{"retry_after":37}}']"
2020-05-25 15:36:02,219 (util.py:66 WorkerThread1) ERROR - TeleBot: "ApiException occurred, args=('A request to the Telegram API was unsuccessful. The server returned HTTP 429 Too Many Requests. Response body:\n[b\'{"ok":false,"error_code":429,"description":"Too Many Requests: retry after 14","parameters":{"retry_after":14}}\']',)
Traceback (most recent call last):
  File "/usr/local/lib/python3.5/dist-packages/telebot/util.py", line 60, in run
    task(*args, **kwargs)
  File "main.py", line 148, in small_random_sentence
    bot.send_message(m.chat.id, generate("history" + str(m.chat.id) + ".txt", SMALL))
  File "/usr/local/lib/python3.5/dist-packages/telebot/__init__.py", line 601, in send_message
    reply_markup, parse_mode, disable_notification, timeout))
  File "/usr/local/lib/python3.5/dist-packages/telebot/apihelper.py", line 154, in send_message
    return _make_request(token, method_url, params=payload, method='post')
  File "/usr/local/lib/python3.5/dist-packages/telebot/apihelper.py", line 60, in _make_request
    return _check_result(method_name, result)['result']
  File "/usr/local/lib/python3.5/dist-packages/telebot/apihelper.py", line 79, in _check_result
    raise ApiException(msg, method_name, result)
telebot.apihelper.ApiException: A request to the Telegram API was unsuccessful. The server returned HTTP 429 Too Many Requests. Response body:
[b'{"ok":false,"error_code":429,"description":"Too Many Requests: retry after 14","parameters":{"retry_after":14}}']
"
2020-05-25 15:36:02,220 (__init__.py:420 MainThread) ERROR - TeleBot: "A request to the Telegram API was unsuccessful. The server returned HTTP 429 Too Many Requests. Response body:
[b'{"ok":false,"error_code":429,"description":"Too Many Requests: retry after 14","parameters":{"retry_after":14}}']"
2020-05-25 15:43:20,873 (util.py:66 PollingThread) ERROR - TeleBot: "ApiException occurred, args=('A request to the Telegram API was unsuccessful. The server returned HTTP 409 Conflict. Response body:\n[b\'{"ok":false,"error_code":409,"description":"Conflict: terminated by other getUpdates request; make sure that only one bot instance is running"}\']',)
Traceback (most recent call last):
  File "/usr/local/lib/python3.5/dist-packages/telebot/util.py", line 60, in run
    task(*args, **kwargs)
  File "/usr/local/lib/python3.5/dist-packages/telebot/__init__.py", line 279, in __retrieve_updates
    updates = self.get_updates(offset=(self.last_update_id + 1), timeout=timeout)
  File "/usr/local/lib/python3.5/dist-packages/telebot/__init__.py", line 249, in get_updates
    json_updates = apihelper.get_updates(self.token, offset, limit, timeout, allowed_updates)
  File "/usr/local/lib/python3.5/dist-packages/telebot/apihelper.py", line 194, in get_updates
    return _make_request(token, method_url, params=payload)
  File "/usr/local/lib/python3.5/dist-packages/telebot/apihelper.py", line 60, in _make_request
    return _check_result(method_name, result)['result']
  File "/usr/local/lib/python3.5/dist-packages/telebot/apihelper.py", line 79, in _check_result
    raise ApiException(msg, method_name, result)
telebot.apihelper.ApiException: A request to the Telegram API was unsuccessful. The server returned HTTP 409 Conflict. Response body:
[b'{"ok":false,"error_code":409,"description":"Conflict: terminated by other getUpdates request; make sure that only one bot instance is running"}']
"
2020-05-25 15:43:20,874 (__init__.py:420 MainThread) ERROR - TeleBot: "A request to the Telegram API was unsuccessful. The server returned HTTP 409 Conflict. Response body:
[b'{"ok":false,"error_code":409,"description":"Conflict: terminated by other getUpdates request; make sure that only one bot instance is running"}']"
2020-05-25 15:43:28,736 (util.py:66 PollingThread) ERROR - TeleBot: "AttributeError occurred, args=("'NoneType' object has no attribute 'lower'",)
Traceback (most recent call last):
  File "/usr/local/lib/python3.5/dist-packages/telebot/util.py", line 60, in run
    task(*args, **kwargs)
  File "/usr/local/lib/python3.5/dist-packages/telebot/__init__.py", line 280, in __retrieve_updates
    self.process_new_updates(updates)
  File "/usr/local/lib/python3.5/dist-packages/telebot/__init__.py", line 317, in process_new_updates
    self.process_new_messages(new_messages)
  File "/usr/local/lib/python3.5/dist-packages/telebot/__init__.py", line 339, in process_new_messages
    self._notify_command_handlers(self.message_handlers, new_messages)
  File "/usr/local/lib/python3.5/dist-packages/telebot/__init__.py", line 1801, in _notify_command_handlers
    if self._test_message_handler(message_handler, message):
  File "/usr/local/lib/python3.5/dist-packages/telebot/__init__.py", line 1769, in _test_message_handler
    if not self._test_filter(filter, filter_value, message):
  File "/usr/local/lib/python3.5/dist-packages/telebot/__init__.py", line 1790, in _test_filter
    return test_cases.get(filter, lambda msg: False)(message)
  File "/usr/local/lib/python3.5/dist-packages/telebot/__init__.py", line 1787, in <lambda>
    'func': lambda msg: filter_value(msg)
  File "main.py", line 197, in <lambda>
    @bot.message_handler(func=lambda message: "сука" in message.text.lower())
AttributeError: 'NoneType' object has no attribute 'lower'
"
Traceback (most recent call last):
  File "main.py", line 256, in <module>
    bot.polling()
  File "/usr/local/lib/python3.5/dist-packages/telebot/__init__.py", line 392, in polling
    self.__threaded_polling(none_stop, interval, timeout)
  File "/usr/local/lib/python3.5/dist-packages/telebot/__init__.py", line 415, in __threaded_polling
    polling_thread.raise_exceptions()
  File "/usr/local/lib/python3.5/dist-packages/telebot/util.py", line 79, in raise_exceptions
    six.reraise(self.exc_info[0], self.exc_info[1], self.exc_info[2])
  File "/usr/lib/python3/dist-packages/six.py", line 686, in reraise
    raise value
  File "/usr/local/lib/python3.5/dist-packages/telebot/util.py", line 60, in run
    task(*args, **kwargs)
  File "/usr/local/lib/python3.5/dist-packages/telebot/__init__.py", line 280, in __retrieve_updates
    self.process_new_updates(updates)
  File "/usr/local/lib/python3.5/dist-packages/telebot/__init__.py", line 317, in process_new_updates
    self.process_new_messages(new_messages)
  File "/usr/local/lib/python3.5/dist-packages/telebot/__init__.py", line 339, in process_new_messages
    self._notify_command_handlers(self.message_handlers, new_messages)
  File "/usr/local/lib/python3.5/dist-packages/telebot/__init__.py", line 1801, in _notify_command_handlers
    if self._test_message_handler(message_handler, message):
  File "/usr/local/lib/python3.5/dist-packages/telebot/__init__.py", line 1769, in _test_message_handler
    if not self._test_filter(filter, filter_value, message):
  File "/usr/local/lib/python3.5/dist-packages/telebot/__init__.py", line 1790, in _test_filter
    return test_cases.get(filter, lambda msg: False)(message)
  File "/usr/local/lib/python3.5/dist-packages/telebot/__init__.py", line 1787, in <lambda>
    'func': lambda msg: filter_value(msg)
  File "main.py", line 197, in <lambda>
    @bot.message_handler(func=lambda message: "сука" in message.text.lower())
AttributeError: 'NoneType' object has no attribute 'lower'
2020-05-25 15:46:53,216 (util.py:66 PollingThread) ERROR - TeleBot: "AttributeError occurred, args=("'NoneType' object has no attribute 'lower'",)
Traceback (most recent call last):
  File "/usr/local/lib/python3.5/dist-packages/telebot/util.py", line 60, in run
    task(*args, **kwargs)
  File "/usr/local/lib/python3.5/dist-packages/telebot/__init__.py", line 280, in __retrieve_updates
    self.process_new_updates(updates)
  File "/usr/local/lib/python3.5/dist-packages/telebot/__init__.py", line 317, in process_new_updates
    self.process_new_messages(new_messages)
  File "/usr/local/lib/python3.5/dist-packages/telebot/__init__.py", line 339, in process_new_messages
    self._notify_command_handlers(self.message_handlers, new_messages)
  File "/usr/local/lib/python3.5/dist-packages/telebot/__init__.py", line 1801, in _notify_command_handlers
    if self._test_message_handler(message_handler, message):
  File "/usr/local/lib/python3.5/dist-packages/telebot/__init__.py", line 1769, in _test_message_handler
    if not self._test_filter(filter, filter_value, message):
  File "/usr/local/lib/python3.5/dist-packages/telebot/__init__.py", line 1790, in _test_filter
    return test_cases.get(filter, lambda msg: False)(message)
  File "/usr/local/lib/python3.5/dist-packages/telebot/__init__.py", line 1787, in <lambda>
    'func': lambda msg: filter_value(msg)
  File "main.py", line 197, in <lambda>
    @bot.message_handler(func=lambda message: "сука" in message.text.lower())
AttributeError: 'NoneType' object has no attribute 'lower'
"
Traceback (most recent call last):
  File "main.py", line 256, in <module>
    bot.polling()
  File "/usr/local/lib/python3.5/dist-packages/telebot/__init__.py", line 392, in polling
    self.__threaded_polling(none_stop, interval, timeout)
  File "/usr/local/lib/python3.5/dist-packages/telebot/__init__.py", line 415, in __threaded_polling
    polling_thread.raise_exceptions()
  File "/usr/local/lib/python3.5/dist-packages/telebot/util.py", line 79, in raise_exceptions
    six.reraise(self.exc_info[0], self.exc_info[1], self.exc_info[2])
  File "/usr/lib/python3/dist-packages/six.py", line 686, in reraise
    raise value
  File "/usr/local/lib/python3.5/dist-packages/telebot/util.py", line 60, in run
    task(*args, **kwargs)
  File "/usr/local/lib/python3.5/dist-packages/telebot/__init__.py", line 280, in __retrieve_updates
    self.process_new_updates(updates)
  File "/usr/local/lib/python3.5/dist-packages/telebot/__init__.py", line 317, in process_new_updates
    self.process_new_messages(new_messages)
  File "/usr/local/lib/python3.5/dist-packages/telebot/__init__.py", line 339, in process_new_messages
    self._notify_command_handlers(self.message_handlers, new_messages)
  File "/usr/local/lib/python3.5/dist-packages/telebot/__init__.py", line 1801, in _notify_command_handlers
    if self._test_message_handler(message_handler, message):
  File "/usr/local/lib/python3.5/dist-packages/telebot/__init__.py", line 1769, in _test_message_handler
    if not self._test_filter(filter, filter_value, message):
  File "/usr/local/lib/python3.5/dist-packages/telebot/__init__.py", line 1790, in _test_filter
    return test_cases.get(filter, lambda msg: False)(message)
  File "/usr/local/lib/python3.5/dist-packages/telebot/__init__.py", line 1787, in <lambda>
    'func': lambda msg: filter_value(msg)
  File "main.py", line 197, in <lambda>
    @bot.message_handler(func=lambda message: "сука" in message.text.lower())
AttributeError: 'NoneType' object has no attribute 'lower'
2020-05-25 15:53:32,899 (util.py:66 PollingThread) ERROR - TeleBot: "ApiException occurred, args=('A request to the Telegram API was unsuccessful. The server returned HTTP 409 Conflict. Response body:\n[b\'{"ok":false,"error_code":409,"description":"Conflict: terminated by other getUpdates request; make sure that only one bot instance is running"}\']',)
Traceback (most recent call last):
  File "/usr/local/lib/python3.5/dist-packages/telebot/util.py", line 60, in run
    task(*args, **kwargs)
  File "/usr/local/lib/python3.5/dist-packages/telebot/__init__.py", line 279, in __retrieve_updates
    updates = self.get_updates(offset=(self.last_update_id + 1), timeout=timeout)
  File "/usr/local/lib/python3.5/dist-packages/telebot/__init__.py", line 249, in get_updates
    json_updates = apihelper.get_updates(self.token, offset, limit, timeout, allowed_updates)
  File "/usr/local/lib/python3.5/dist-packages/telebot/apihelper.py", line 194, in get_updates
    return _make_request(token, method_url, params=payload)
  File "/usr/local/lib/python3.5/dist-packages/telebot/apihelper.py", line 60, in _make_request
    return _check_result(method_name, result)['result']
  File "/usr/local/lib/python3.5/dist-packages/telebot/apihelper.py", line 79, in _check_result
    raise ApiException(msg, method_name, result)
telebot.apihelper.ApiException: A request to the Telegram API was unsuccessful. The server returned HTTP 409 Conflict. Response body:
[b'{"ok":false,"error_code":409,"description":"Conflict: terminated by other getUpdates request; make sure that only one bot instance is running"}']
"
2020-05-25 15:53:32,899 (__init__.py:420 MainThread) ERROR - TeleBot: "A request to the Telegram API was unsuccessful. The server returned HTTP 409 Conflict. Response body:
[b'{"ok":false,"error_code":409,"description":"Conflict: terminated by other getUpdates request; make sure that only one bot instance is running"}']"
2020-05-25 16:06:02,142 (util.py:66 PollingThread) ERROR - TeleBot: "ApiException occurred, args=('A request to the Telegram API was unsuccessful. The server returned HTTP 409 Conflict. Response body:\n[b\'{"ok":false,"error_code":409,"description":"Conflict: terminated by other getUpdates request; make sure that only one bot instance is running"}\']',)
Traceback (most recent call last):
  File "/usr/local/lib/python3.5/dist-packages/telebot/util.py", line 60, in run
    task(*args, **kwargs)
  File "/usr/local/lib/python3.5/dist-packages/telebot/__init__.py", line 279, in __retrieve_updates
    updates = self.get_updates(offset=(self.last_update_id + 1), timeout=timeout)
  File "/usr/local/lib/python3.5/dist-packages/telebot/__init__.py", line 249, in get_updates
    json_updates = apihelper.get_updates(self.token, offset, limit, timeout, allowed_updates)
  File "/usr/local/lib/python3.5/dist-packages/telebot/apihelper.py", line 194, in get_updates
    return _make_request(token, method_url, params=payload)
  File "/usr/local/lib/python3.5/dist-packages/telebot/apihelper.py", line 60, in _make_request
    return _check_result(method_name, result)['result']
  File "/usr/local/lib/python3.5/dist-packages/telebot/apihelper.py", line 79, in _check_result
    raise ApiException(msg, method_name, result)
telebot.apihelper.ApiException: A request to the Telegram API was unsuccessful. The server returned HTTP 409 Conflict. Response body:
[b'{"ok":false,"error_code":409,"description":"Conflict: terminated by other getUpdates request; make sure that only one bot instance is running"}']
"
2020-05-25 16:06:02,142 (__init__.py:420 MainThread) ERROR - TeleBot: "A request to the Telegram API was unsuccessful. The server returned HTTP 409 Conflict. Response body:
[b'{"ok":false,"error_code":409,"description":"Conflict: terminated by other getUpdates request; make sure that only one bot instance is running"}']"
2020-05-25 16:06:07,263 (util.py:66 PollingThread) ERROR - TeleBot: "ApiException occurred, args=('A request to the Telegram API was unsuccessful. The server returned HTTP 409 Conflict. Response body:\n[b\'{"ok":false,"error_code":409,"description":"Conflict: terminated by other getUpdates request; make sure that only one bot instance is running"}\']',)
Traceback (most recent call last):
  File "/usr/local/lib/python3.5/dist-packages/telebot/util.py", line 60, in run
    task(*args, **kwargs)
  File "/usr/local/lib/python3.5/dist-packages/telebot/__init__.py", line 279, in __retrieve_updates
    updates = self.get_updates(offset=(self.last_update_id + 1), timeout=timeout)
  File "/usr/local/lib/python3.5/dist-packages/telebot/__init__.py", line 249, in get_updates
    json_updates = apihelper.get_updates(self.token, offset, limit, timeout, allowed_updates)
  File "/usr/local/lib/python3.5/dist-packages/telebot/apihelper.py", line 194, in get_updates
    return _make_request(token, method_url, params=payload)
  File "/usr/local/lib/python3.5/dist-packages/telebot/apihelper.py", line 60, in _make_request
    return _check_result(method_name, result)['result']
  File "/usr/local/lib/python3.5/dist-packages/telebot/apihelper.py", line 79, in _check_result
    raise ApiException(msg, method_name, result)
telebot.apihelper.ApiException: A request to the Telegram API was unsuccessful. The server returned HTTP 409 Conflict. Response body:
[b'{"ok":false,"error_code":409,"description":"Conflict: terminated by other getUpdates request; make sure that only one bot instance is running"}']
"
2020-05-25 16:06:07,264 (__init__.py:420 MainThread) ERROR - TeleBot: "A request to the Telegram API was unsuccessful. The server returned HTTP 409 Conflict. Response body:
[b'{"ok":false,"error_code":409,"description":"Conflict: terminated by other getUpdates request; make sure that only one bot instance is running"}']"
2020-05-25 17:09:01,229 (util.py:66 WorkerThread1) ERROR - TeleBot: "TypeError occurred, args=("'Message' object is not iterable",)
Traceback (most recent call last):
  File "/usr/local/lib/python3.5/dist-packages/telebot/util.py", line 60, in run
    task(*args, **kwargs)
  File "main.py", line 74, in listener
    for m in messages:
TypeError: 'Message' object is not iterable
"
Traceback (most recent call last):
  File "main.py", line 263, in <module>
    bot.polling()
  File "/usr/local/lib/python3.5/dist-packages/telebot/__init__.py", line 392, in polling
    self.__threaded_polling(none_stop, interval, timeout)
  File "/usr/local/lib/python3.5/dist-packages/telebot/__init__.py", line 416, in __threaded_polling
    self.worker_pool.raise_exceptions()
  File "/usr/local/lib/python3.5/dist-packages/telebot/util.py", line 109, in raise_exceptions
    six.reraise(self.exc_info[0], self.exc_info[1], self.exc_info[2])
  File "/usr/lib/python3/dist-packages/six.py", line 686, in reraise
    raise value
  File "/usr/local/lib/python3.5/dist-packages/telebot/util.py", line 60, in run
    task(*args, **kwargs)
  File "main.py", line 74, in listener
    for m in messages:
TypeError: 'Message' object is not iterable
2020-05-26 05:44:17,735 (util.py:66 PollingThread) ERROR - TeleBot: "ApiException occurred, args=('A request to the Telegram API was unsuccessful. The server returned HTTP 409 Conflict. Response body:\n[b\'{"ok":false,"error_code":409,"description":"Conflict: terminated by other getUpdates request; make sure that only one bot instance is running"}\']',)
Traceback (most recent call last):
  File "/usr/local/lib/python3.5/dist-packages/telebot/util.py", line 60, in run
    task(*args, **kwargs)
  File "/usr/local/lib/python3.5/dist-packages/telebot/__init__.py", line 279, in __retrieve_updates
    updates = self.get_updates(offset=(self.last_update_id + 1), timeout=timeout)
  File "/usr/local/lib/python3.5/dist-packages/telebot/__init__.py", line 249, in get_updates
    json_updates = apihelper.get_updates(self.token, offset, limit, timeout, allowed_updates)
  File "/usr/local/lib/python3.5/dist-packages/telebot/apihelper.py", line 194, in get_updates
    return _make_request(token, method_url, params=payload)
  File "/usr/local/lib/python3.5/dist-packages/telebot/apihelper.py", line 60, in _make_request
    return _check_result(method_name, result)['result']
  File "/usr/local/lib/python3.5/dist-packages/telebot/apihelper.py", line 79, in _check_result
    raise ApiException(msg, method_name, result)
telebot.apihelper.ApiException: A request to the Telegram API was unsuccessful. The server returned HTTP 409 Conflict. Response body:
[b'{"ok":false,"error_code":409,"description":"Conflict: terminated by other getUpdates request; make sure that only one bot instance is running"}']
"
2020-05-26 05:44:17,735 (__init__.py:420 MainThread) ERROR - TeleBot: "A request to the Telegram API was unsuccessful. The server returned HTTP 409 Conflict. Response body:
[b'{"ok":false,"error_code":409,"description":"Conflict: terminated by other getUpdates request; make sure that only one bot instance is running"}']"
2020-05-27 04:13:08,899 (util.py:66 WorkerThread1) ERROR - TeleBot: "TypeError occurred, args=("'Message' object is not iterable",)
Traceback (most recent call last):
  File "/usr/local/lib/python3.5/dist-packages/telebot/util.py", line 60, in run
    task(*args, **kwargs)
  File "main.py", line 74, in listener
    for m in messages:
TypeError: 'Message' object is not iterable
"
Traceback (most recent call last):
  File "main.py", line 265, in <module>
    bot.polling()
  File "/usr/local/lib/python3.5/dist-packages/telebot/__init__.py", line 392, in polling
    self.__threaded_polling(none_stop, interval, timeout)
  File "/usr/local/lib/python3.5/dist-packages/telebot/__init__.py", line 416, in __threaded_polling
    self.worker_pool.raise_exceptions()
  File "/usr/local/lib/python3.5/dist-packages/telebot/util.py", line 109, in raise_exceptions
    six.reraise(self.exc_info[0], self.exc_info[1], self.exc_info[2])
  File "/usr/lib/python3/dist-packages/six.py", line 686, in reraise
    raise value
  File "/usr/local/lib/python3.5/dist-packages/telebot/util.py", line 60, in run
    task(*args, **kwargs)
  File "main.py", line 74, in listener
    for m in messages:
TypeError: 'Message' object is not iterable
2020-05-27 19:23:17,676 (util.py:66 WorkerThread2) ERROR - TeleBot: "TypeError occurred, args=("'Message' object is not iterable",)
Traceback (most recent call last):
  File "/usr/local/lib/python3.5/dist-packages/telebot/util.py", line 60, in run
    task(*args, **kwargs)
  File "main.py", line 74, in listener
    for m in messages:
TypeError: 'Message' object is not iterable
"
Traceback (most recent call last):
  File "main.py", line 265, in <module>
    bot.polling()
  File "/usr/local/lib/python3.5/dist-packages/telebot/__init__.py", line 392, in polling
    self.__threaded_polling(none_stop, interval, timeout)
  File "/usr/local/lib/python3.5/dist-packages/telebot/__init__.py", line 416, in __threaded_polling
    self.worker_pool.raise_exceptions()
  File "/usr/local/lib/python3.5/dist-packages/telebot/util.py", line 109, in raise_exceptions
    six.reraise(self.exc_info[0], self.exc_info[1], self.exc_info[2])
  File "/usr/lib/python3/dist-packages/six.py", line 686, in reraise
    raise value
  File "/usr/local/lib/python3.5/dist-packages/telebot/util.py", line 60, in run
    task(*args, **kwargs)
  File "main.py", line 74, in listener
    for m in messages:
TypeError: 'Message' object is not iterable
2020-05-27 19:29:40,046 (util.py:66 PollingThread) ERROR - TeleBot: "ApiException occurred, args=('A request to the Telegram API was unsuccessful. The server returned HTTP 409 Conflict. Response body:\n[b\'{"ok":false,"error_code":409,"description":"Conflict: terminated by other getUpdates request; make sure that only one bot instance is running"}\']',)
Traceback (most recent call last):
  File "/usr/local/lib/python3.5/dist-packages/telebot/util.py", line 60, in run
    task(*args, **kwargs)
  File "/usr/local/lib/python3.5/dist-packages/telebot/__init__.py", line 279, in __retrieve_updates
    updates = self.get_updates(offset=(self.last_update_id + 1), timeout=timeout)
  File "/usr/local/lib/python3.5/dist-packages/telebot/__init__.py", line 249, in get_updates
    json_updates = apihelper.get_updates(self.token, offset, limit, timeout, allowed_updates)
  File "/usr/local/lib/python3.5/dist-packages/telebot/apihelper.py", line 194, in get_updates
    return _make_request(token, method_url, params=payload)
  File "/usr/local/lib/python3.5/dist-packages/telebot/apihelper.py", line 60, in _make_request
    return _check_result(method_name, result)['result']
  File "/usr/local/lib/python3.5/dist-packages/telebot/apihelper.py", line 79, in _check_result
    raise ApiException(msg, method_name, result)
telebot.apihelper.ApiException: A request to the Telegram API was unsuccessful. The server returned HTTP 409 Conflict. Response body:
[b'{"ok":false,"error_code":409,"description":"Conflict: terminated by other getUpdates request; make sure that only one bot instance is running"}']
"
2020-05-27 19:29:40,046 (__init__.py:420 MainThread) ERROR - TeleBot: "A request to the Telegram API was unsuccessful. The server returned HTTP 409 Conflict. Response body:
[b'{"ok":false,"error_code":409,"description":"Conflict: terminated by other getUpdates request; make sure that only one bot instance is running"}']"
2020-05-27 19:42:03,614 (util.py:66 WorkerThread1) ERROR - TeleBot: "FileNotFoundError occurred, args=(2, 'No such file or directory')
Traceback (most recent call last):
  File "/usr/local/lib/python3.5/dist-packages/telebot/util.py", line 60, in run
    task(*args, **kwargs)
  File "main.py", line 136, in random_sentence
    bot.send_message(m.chat.id, generate("history" + str(m.chat.id) + ".txt", random.randint(SMALL, LARGE)))
  File "main.py", line 218, in generate
    file = open(filename, "r")
FileNotFoundError: [Errno 2] No such file or directory: 'history-432762228.txt'
"
Traceback (most recent call last):
  File "main.py", line 265, in <module>
    bot.polling()
  File "/usr/local/lib/python3.5/dist-packages/telebot/__init__.py", line 392, in polling
    self.__threaded_polling(none_stop, interval, timeout)
  File "/usr/local/lib/python3.5/dist-packages/telebot/__init__.py", line 416, in __threaded_polling
    self.worker_pool.raise_exceptions()
  File "/usr/local/lib/python3.5/dist-packages/telebot/util.py", line 109, in raise_exceptions
    six.reraise(self.exc_info[0], self.exc_info[1], self.exc_info[2])
  File "/usr/lib/python3/dist-packages/six.py", line 686, in reraise
    raise value
  File "/usr/local/lib/python3.5/dist-packages/telebot/util.py", line 60, in run
    task(*args, **kwargs)
  File "main.py", line 136, in random_sentence
    bot.send_message(m.chat.id, generate("history" + str(m.chat.id) + ".txt", random.randint(SMALL, LARGE)))
  File "main.py", line 218, in generate
    file = open(filename, "r")
FileNotFoundError: [Errno 2] No such file or directory: 'history-432762228.txt'
2020-05-28 12:04:58,126 (util.py:66 PollingThread) ERROR - TeleBot: "ApiException occurred, args=('A request to the Telegram API was unsuccessful. The server returned HTTP 409 Conflict. Response body:\n[b\'{"ok":false,"error_code":409,"description":"Conflict: terminated by other getUpdates request; make sure that only one bot instance is running"}\']',)
Traceback (most recent call last):
  File "/usr/local/lib/python3.5/dist-packages/telebot/util.py", line 60, in run
    task(*args, **kwargs)
  File "/usr/local/lib/python3.5/dist-packages/telebot/__init__.py", line 279, in __retrieve_updates
    updates = self.get_updates(offset=(self.last_update_id + 1), timeout=timeout)
  File "/usr/local/lib/python3.5/dist-packages/telebot/__init__.py", line 249, in get_updates
    json_updates = apihelper.get_updates(self.token, offset, limit, timeout, allowed_updates)
  File "/usr/local/lib/python3.5/dist-packages/telebot/apihelper.py", line 194, in get_updates
    return _make_request(token, method_url, params=payload)
  File "/usr/local/lib/python3.5/dist-packages/telebot/apihelper.py", line 60, in _make_request
    return _check_result(method_name, result)['result']
  File "/usr/local/lib/python3.5/dist-packages/telebot/apihelper.py", line 79, in _check_result
    raise ApiException(msg, method_name, result)
telebot.apihelper.ApiException: A request to the Telegram API was unsuccessful. The server returned HTTP 409 Conflict. Response body:
[b'{"ok":false,"error_code":409,"description":"Conflict: terminated by other getUpdates request; make sure that only one bot instance is running"}']
"
2020-05-28 12:04:58,127 (__init__.py:420 MainThread) ERROR - TeleBot: "A request to the Telegram API was unsuccessful. The server returned HTTP 409 Conflict. Response body:
[b'{"ok":false,"error_code":409,"description":"Conflict: terminated by other getUpdates request; make sure that only one bot instance is running"}']"
2020-05-28 12:08:59,316 (util.py:66 PollingThread) ERROR - TeleBot: "ApiException occurred, args=('A request to the Telegram API was unsuccessful. The server returned HTTP 409 Conflict. Response body:\n[b\'{"ok":false,"error_code":409,"description":"Conflict: terminated by other getUpdates request; make sure that only one bot instance is running"}\']',)
Traceback (most recent call last):
  File "/usr/local/lib/python3.5/dist-packages/telebot/util.py", line 60, in run
    task(*args, **kwargs)
  File "/usr/local/lib/python3.5/dist-packages/telebot/__init__.py", line 279, in __retrieve_updates
    updates = self.get_updates(offset=(self.last_update_id + 1), timeout=timeout)
  File "/usr/local/lib/python3.5/dist-packages/telebot/__init__.py", line 249, in get_updates
    json_updates = apihelper.get_updates(self.token, offset, limit, timeout, allowed_updates)
  File "/usr/local/lib/python3.5/dist-packages/telebot/apihelper.py", line 194, in get_updates
    return _make_request(token, method_url, params=payload)
  File "/usr/local/lib/python3.5/dist-packages/telebot/apihelper.py", line 60, in _make_request
    return _check_result(method_name, result)['result']
  File "/usr/local/lib/python3.5/dist-packages/telebot/apihelper.py", line 79, in _check_result
    raise ApiException(msg, method_name, result)
telebot.apihelper.ApiException: A request to the Telegram API was unsuccessful. The server returned HTTP 409 Conflict. Response body:
[b'{"ok":false,"error_code":409,"description":"Conflict: terminated by other getUpdates request; make sure that only one bot instance is running"}']
"
2020-05-28 12:08:59,317 (__init__.py:420 MainThread) ERROR - TeleBot: "A request to the Telegram API was unsuccessful. The server returned HTTP 409 Conflict. Response body:
[b'{"ok":false,"error_code":409,"description":"Conflict: terminated by other getUpdates request; make sure that only one bot instance is running"}']"
2020-05-28 16:09:59,807 (util.py:66 PollingThread) ERROR - TeleBot: "ApiException occurred, args=('A request to the Telegram API was unsuccessful. The server returned HTTP 409 Conflict. Response body:\n[b\'{"ok":false,"error_code":409,"description":"Conflict: terminated by other getUpdates request; make sure that only one bot instance is running"}\']',)
Traceback (most recent call last):
  File "/usr/local/lib/python3.5/dist-packages/telebot/util.py", line 60, in run
    task(*args, **kwargs)
  File "/usr/local/lib/python3.5/dist-packages/telebot/__init__.py", line 279, in __retrieve_updates
    updates = self.get_updates(offset=(self.last_update_id + 1), timeout=timeout)
  File "/usr/local/lib/python3.5/dist-packages/telebot/__init__.py", line 249, in get_updates
    json_updates = apihelper.get_updates(self.token, offset, limit, timeout, allowed_updates)
  File "/usr/local/lib/python3.5/dist-packages/telebot/apihelper.py", line 194, in get_updates
    return _make_request(token, method_url, params=payload)
  File "/usr/local/lib/python3.5/dist-packages/telebot/apihelper.py", line 60, in _make_request
    return _check_result(method_name, result)['result']
  File "/usr/local/lib/python3.5/dist-packages/telebot/apihelper.py", line 79, in _check_result
    raise ApiException(msg, method_name, result)
telebot.apihelper.ApiException: A request to the Telegram API was unsuccessful. The server returned HTTP 409 Conflict. Response body:
[b'{"ok":false,"error_code":409,"description":"Conflict: terminated by other getUpdates request; make sure that only one bot instance is running"}']
"
2020-05-28 16:09:59,807 (__init__.py:420 MainThread) ERROR - TeleBot: "A request to the Telegram API was unsuccessful. The server returned HTTP 409 Conflict. Response body:
[b'{"ok":false,"error_code":409,"description":"Conflict: terminated by other getUpdates request; make sure that only one bot instance is running"}']"
2020-05-28 16:11:11,043 (util.py:66 PollingThread) ERROR - TeleBot: "ApiException occurred, args=('A request to the Telegram API was unsuccessful. The server returned HTTP 409 Conflict. Response body:\n[b\'{"ok":false,"error_code":409,"description":"Conflict: terminated by other getUpdates request; make sure that only one bot instance is running"}\']',)
Traceback (most recent call last):
  File "/usr/local/lib/python3.5/dist-packages/telebot/util.py", line 60, in run
    task(*args, **kwargs)
  File "/usr/local/lib/python3.5/dist-packages/telebot/__init__.py", line 279, in __retrieve_updates
    updates = self.get_updates(offset=(self.last_update_id + 1), timeout=timeout)
  File "/usr/local/lib/python3.5/dist-packages/telebot/__init__.py", line 249, in get_updates
    json_updates = apihelper.get_updates(self.token, offset, limit, timeout, allowed_updates)
  File "/usr/local/lib/python3.5/dist-packages/telebot/apihelper.py", line 194, in get_updates
    return _make_request(token, method_url, params=payload)
  File "/usr/local/lib/python3.5/dist-packages/telebot/apihelper.py", line 60, in _make_request
    return _check_result(method_name, result)['result']
  File "/usr/local/lib/python3.5/dist-packages/telebot/apihelper.py", line 79, in _check_result
    raise ApiException(msg, method_name, result)
telebot.apihelper.ApiException: A request to the Telegram API was unsuccessful. The server returned HTTP 409 Conflict. Response body:
[b'{"ok":false,"error_code":409,"description":"Conflict: terminated by other getUpdates request; make sure that only one bot instance is running"}']
"
2020-05-28 16:11:11,044 (__init__.py:420 MainThread) ERROR - TeleBot: "A request to the Telegram API was unsuccessful. The server returned HTTP 409 Conflict. Response body:
[b'{"ok":false,"error_code":409,"description":"Conflict: terminated by other getUpdates request; make sure that only one bot instance is running"}']"
2020-05-28 16:17:22,905 (util.py:66 WorkerThread1) ERROR - TeleBot: "TypeError occurred, args=("'Message' object is not iterable",)
Traceback (most recent call last):
  File "/usr/local/lib/python3.5/dist-packages/telebot/util.py", line 60, in run
    task(*args, **kwargs)
  File "main.py", line 76, in listener
    for m in messages:
TypeError: 'Message' object is not iterable
"
Traceback (most recent call last):
  File "main.py", line 280, in <module>
    bot.polling()
  File "/usr/local/lib/python3.5/dist-packages/telebot/__init__.py", line 392, in polling
    self.__threaded_polling(none_stop, interval, timeout)
  File "/usr/local/lib/python3.5/dist-packages/telebot/__init__.py", line 416, in __threaded_polling
    self.worker_pool.raise_exceptions()
  File "/usr/local/lib/python3.5/dist-packages/telebot/util.py", line 109, in raise_exceptions
    six.reraise(self.exc_info[0], self.exc_info[1], self.exc_info[2])
  File "/usr/lib/python3/dist-packages/six.py", line 686, in reraise
    raise value
  File "/usr/local/lib/python3.5/dist-packages/telebot/util.py", line 60, in run
    task(*args, **kwargs)
  File "main.py", line 76, in listener
    for m in messages:
TypeError: 'Message' object is not iterable
2020-05-28 16:18:10,875 (util.py:66 WorkerThread2) ERROR - TeleBot: "TypeError occurred, args=("'Message' object is not iterable",)
Traceback (most recent call last):
  File "/usr/local/lib/python3.5/dist-packages/telebot/util.py", line 60, in run
    task(*args, **kwargs)
  File "main.py", line 76, in listener
    for m in messages:
TypeError: 'Message' object is not iterable
"
Traceback (most recent call last):
  File "main.py", line 280, in <module>
    bot.polling()
  File "/usr/local/lib/python3.5/dist-packages/telebot/__init__.py", line 392, in polling
    self.__threaded_polling(none_stop, interval, timeout)
  File "/usr/local/lib/python3.5/dist-packages/telebot/__init__.py", line 416, in __threaded_polling
    self.worker_pool.raise_exceptions()
  File "/usr/local/lib/python3.5/dist-packages/telebot/util.py", line 109, in raise_exceptions
    six.reraise(self.exc_info[0], self.exc_info[1], self.exc_info[2])
  File "/usr/lib/python3/dist-packages/six.py", line 686, in reraise
    raise value
  File "/usr/local/lib/python3.5/dist-packages/telebot/util.py", line 60, in run
    task(*args, **kwargs)
  File "main.py", line 76, in listener
    for m in messages:
TypeError: 'Message' object is not iterable
2020-05-28 16:19:43,550 (util.py:66 WorkerThread1) ERROR - TeleBot: "TypeError occurred, args=("'Message' object is not iterable",)
Traceback (most recent call last):
  File "/usr/local/lib/python3.5/dist-packages/telebot/util.py", line 60, in run
    task(*args, **kwargs)
  File "main.py", line 76, in listener
    for m in messages:
TypeError: 'Message' object is not iterable
"
Traceback (most recent call last):
  File "main.py", line 280, in <module>
    bot.polling()
  File "/usr/local/lib/python3.5/dist-packages/telebot/__init__.py", line 392, in polling
    self.__threaded_polling(none_stop, interval, timeout)
  File "/usr/local/lib/python3.5/dist-packages/telebot/__init__.py", line 416, in __threaded_polling
    self.worker_pool.raise_exceptions()
  File "/usr/local/lib/python3.5/dist-packages/telebot/util.py", line 109, in raise_exceptions
    six.reraise(self.exc_info[0], self.exc_info[1], self.exc_info[2])
  File "/usr/lib/python3/dist-packages/six.py", line 686, in reraise
    raise value
  File "/usr/local/lib/python3.5/dist-packages/telebot/util.py", line 60, in run
    task(*args, **kwargs)
  File "main.py", line 76, in listener
    for m in messages:
TypeError: 'Message' object is not iterable
2020-05-28 16:21:09,708 (util.py:66 WorkerThread2) ERROR - TeleBot: "TypeError occurred, args=("'Message' object is not iterable",)
Traceback (most recent call last):
  File "/usr/local/lib/python3.5/dist-packages/telebot/util.py", line 60, in run
    task(*args, **kwargs)
  File "main.py", line 76, in listener
    for m in messages:
TypeError: 'Message' object is not iterable
"
Traceback (most recent call last):
  File "main.py", line 280, in <module>
    bot.polling()
  File "/usr/local/lib/python3.5/dist-packages/telebot/__init__.py", line 392, in polling
    self.__threaded_polling(none_stop, interval, timeout)
  File "/usr/local/lib/python3.5/dist-packages/telebot/__init__.py", line 416, in __threaded_polling
    self.worker_pool.raise_exceptions()
  File "/usr/local/lib/python3.5/dist-packages/telebot/util.py", line 109, in raise_exceptions
    six.reraise(self.exc_info[0], self.exc_info[1], self.exc_info[2])
  File "/usr/lib/python3/dist-packages/six.py", line 686, in reraise
    raise value
  File "/usr/local/lib/python3.5/dist-packages/telebot/util.py", line 60, in run
    task(*args, **kwargs)
  File "main.py", line 76, in listener
    for m in messages:
TypeError: 'Message' object is not iterable
2020-05-28 16:21:26,038 (util.py:66 WorkerThread2) ERROR - TeleBot: "TypeError occurred, args=("'Message' object is not iterable",)
Traceback (most recent call last):
  File "/usr/local/lib/python3.5/dist-packages/telebot/util.py", line 60, in run
    task(*args, **kwargs)
  File "main.py", line 76, in listener
    for m in messages:
TypeError: 'Message' object is not iterable
"
Traceback (most recent call last):
  File "main.py", line 280, in <module>
    bot.polling()
  File "/usr/local/lib/python3.5/dist-packages/telebot/__init__.py", line 392, in polling
    self.__threaded_polling(none_stop, interval, timeout)
  File "/usr/local/lib/python3.5/dist-packages/telebot/__init__.py", line 416, in __threaded_polling
    self.worker_pool.raise_exceptions()
  File "/usr/local/lib/python3.5/dist-packages/telebot/util.py", line 109, in raise_exceptions
    six.reraise(self.exc_info[0], self.exc_info[1], self.exc_info[2])
  File "/usr/lib/python3/dist-packages/six.py", line 686, in reraise
    raise value
  File "/usr/local/lib/python3.5/dist-packages/telebot/util.py", line 60, in run
    task(*args, **kwargs)
  File "main.py", line 76, in listener
    for m in messages:
TypeError: 'Message' object is not iterable
2020-05-28 16:31:27,461 (util.py:66 PollingThread) ERROR - TeleBot: "ApiException occurred, args=('A request to the Telegram API was unsuccessful. The server returned HTTP 409 Conflict. Response body:\n[b\'{"ok":false,"error_code":409,"description":"Conflict: terminated by other getUpdates request; make sure that only one bot instance is running"}\']',)
Traceback (most recent call last):
  File "/usr/local/lib/python3.5/dist-packages/telebot/util.py", line 60, in run
    task(*args, **kwargs)
  File "/usr/local/lib/python3.5/dist-packages/telebot/__init__.py", line 279, in __retrieve_updates
    updates = self.get_updates(offset=(self.last_update_id + 1), timeout=timeout)
  File "/usr/local/lib/python3.5/dist-packages/telebot/__init__.py", line 249, in get_updates
    json_updates = apihelper.get_updates(self.token, offset, limit, timeout, allowed_updates)
  File "/usr/local/lib/python3.5/dist-packages/telebot/apihelper.py", line 194, in get_updates
    return _make_request(token, method_url, params=payload)
  File "/usr/local/lib/python3.5/dist-packages/telebot/apihelper.py", line 60, in _make_request
    return _check_result(method_name, result)['result']
  File "/usr/local/lib/python3.5/dist-packages/telebot/apihelper.py", line 79, in _check_result
    raise ApiException(msg, method_name, result)
telebot.apihelper.ApiException: A request to the Telegram API was unsuccessful. The server returned HTTP 409 Conflict. Response body:
[b'{"ok":false,"error_code":409,"description":"Conflict: terminated by other getUpdates request; make sure that only one bot instance is running"}']
"
2020-05-28 16:31:27,461 (__init__.py:420 MainThread) ERROR - TeleBot: "A request to the Telegram API was unsuccessful. The server returned HTTP 409 Conflict. Response body:
[b'{"ok":false,"error_code":409,"description":"Conflict: terminated by other getUpdates request; make sure that only one bot instance is running"}']"
  File "main.py", line 141
    else
       ^
SyntaxError: invalid syntax
2020-05-28 16:34:28,811 (util.py:66 PollingThread) ERROR - TeleBot: "ApiException occurred, args=('A request to the Telegram API was unsuccessful. The server returned HTTP 409 Conflict. Response body:\n[b\'{"ok":false,"error_code":409,"description":"Conflict: terminated by other getUpdates request; make sure that only one bot instance is running"}\']',)
Traceback (most recent call last):
  File "/usr/local/lib/python3.5/dist-packages/telebot/util.py", line 60, in run
    task(*args, **kwargs)
  File "/usr/local/lib/python3.5/dist-packages/telebot/__init__.py", line 279, in __retrieve_updates
    updates = self.get_updates(offset=(self.last_update_id + 1), timeout=timeout)
  File "/usr/local/lib/python3.5/dist-packages/telebot/__init__.py", line 249, in get_updates
    json_updates = apihelper.get_updates(self.token, offset, limit, timeout, allowed_updates)
  File "/usr/local/lib/python3.5/dist-packages/telebot/apihelper.py", line 194, in get_updates
    return _make_request(token, method_url, params=payload)
  File "/usr/local/lib/python3.5/dist-packages/telebot/apihelper.py", line 60, in _make_request
    return _check_result(method_name, result)['result']
  File "/usr/local/lib/python3.5/dist-packages/telebot/apihelper.py", line 79, in _check_result
    raise ApiException(msg, method_name, result)
telebot.apihelper.ApiException: A request to the Telegram API was unsuccessful. The server returned HTTP 409 Conflict. Response body:
[b'{"ok":false,"error_code":409,"description":"Conflict: terminated by other getUpdates request; make sure that only one bot instance is running"}']
"
2020-05-28 16:34:28,811 (__init__.py:420 MainThread) ERROR - TeleBot: "A request to the Telegram API was unsuccessful. The server returned HTTP 409 Conflict. Response body:
[b'{"ok":false,"error_code":409,"description":"Conflict: terminated by other getUpdates request; make sure that only one bot instance is running"}']"
2020-05-29 10:48:36,961 (util.py:66 PollingThread) ERROR - TeleBot: "ApiException occurred, args=('A request to the Telegram API was unsuccessful. The server returned HTTP 409 Conflict. Response body:\n[b\'{"ok":false,"error_code":409,"description":"Conflict: terminated by other getUpdates request; make sure that only one bot instance is running"}\']',)
Traceback (most recent call last):
  File "/usr/local/lib/python3.5/dist-packages/telebot/util.py", line 60, in run
    task(*args, **kwargs)
  File "/usr/local/lib/python3.5/dist-packages/telebot/__init__.py", line 279, in __retrieve_updates
    updates = self.get_updates(offset=(self.last_update_id + 1), timeout=timeout)
  File "/usr/local/lib/python3.5/dist-packages/telebot/__init__.py", line 249, in get_updates
    json_updates = apihelper.get_updates(self.token, offset, limit, timeout, allowed_updates)
  File "/usr/local/lib/python3.5/dist-packages/telebot/apihelper.py", line 194, in get_updates
    return _make_request(token, method_url, params=payload)
  File "/usr/local/lib/python3.5/dist-packages/telebot/apihelper.py", line 60, in _make_request
    return _check_result(method_name, result)['result']
  File "/usr/local/lib/python3.5/dist-packages/telebot/apihelper.py", line 79, in _check_result
    raise ApiException(msg, method_name, result)
telebot.apihelper.ApiException: A request to the Telegram API was unsuccessful. The server returned HTTP 409 Conflict. Response body:
[b'{"ok":false,"error_code":409,"description":"Conflict: terminated by other getUpdates request; make sure that only one bot instance is running"}']
"
2020-05-29 10:48:36,961 (__init__.py:420 MainThread) ERROR - TeleBot: "A request to the Telegram API was unsuccessful. The server returned HTTP 409 Conflict. Response body:
[b'{"ok":false,"error_code":409,"description":"Conflict: terminated by other getUpdates request; make sure that only one bot instance is running"}']"
2020-05-29 11:00:34,523 (util.py:66 WorkerThread1) ERROR - TeleBot: "AttributeError occurred, args=("'NoneType' object has no attribute 'lower'",)
Traceback (most recent call last):
  File "/usr/local/lib/python3.5/dist-packages/telebot/util.py", line 60, in run
    task(*args, **kwargs)
  File "Pika.py", line 40, in send_text
    if message.text.lower() == 'êîìàíäû':
AttributeError: 'NoneType' object has no attribute 'lower'
"
2020-05-29 11:00:34,524 (util.py:66 WorkerThread1) ERROR - TeleBot: "AttributeError occurred, args=("'NoneType' object has no attribute 'lower'",)
Traceback (most recent call last):
  File "/usr/local/lib/python3.5/dist-packages/telebot/util.py", line 60, in run
    task(*args, **kwargs)
  File "Pika.py", line 40, in send_text
    if message.text.lower() == 'êîìàíäû':
AttributeError: 'NoneType' object has no attribute 'lower'
"
2020-05-29 11:00:34,525 (util.py:66 WorkerThread1) ERROR - TeleBot: "AttributeError occurred, args=("'NoneType' object has no attribute 'lower'",)
Traceback (most recent call last):
  File "/usr/local/lib/python3.5/dist-packages/telebot/util.py", line 60, in run
    task(*args, **kwargs)
  File "Pika.py", line 40, in send_text
    if message.text.lower() == 'êîìàíäû':
AttributeError: 'NoneType' object has no attribute 'lower'
"
Traceback (most recent call last):
  File "Pika.py", line 344, in <module>
    bot.polling(none_stop=True, interval=0)
  File "/usr/local/lib/python3.5/dist-packages/telebot/__init__.py", line 392, in polling
    self.__threaded_polling(none_stop, interval, timeout)
  File "/usr/local/lib/python3.5/dist-packages/telebot/__init__.py", line 416, in __threaded_polling
    self.worker_pool.raise_exceptions()
  File "/usr/local/lib/python3.5/dist-packages/telebot/util.py", line 109, in raise_exceptions
    six.reraise(self.exc_info[0], self.exc_info[1], self.exc_info[2])
  File "/usr/lib/python3/dist-packages/six.py", line 686, in reraise
    raise value
  File "/usr/local/lib/python3.5/dist-packages/telebot/util.py", line 60, in run
    task(*args, **kwargs)
  File "Pika.py", line 40, in send_text
    if message.text.lower() == 'êîìàíäû':
AttributeError: 'NoneType' object has no attribute 'lower'
2020-05-29 11:01:11,074 (util.py:66 WorkerThread2) ERROR - TeleBot: "IndexError occurred, args=('list index out of range',)
Traceback (most recent call last):
  File "/usr/local/lib/python3.5/dist-packages/telebot/util.py", line 60, in run
    task(*args, **kwargs)
  File "main.py", line 81, in listener
    text_to_speech(m)
  File "main.py", line 120, in text_to_speech
    tts = gTTS(strs[1], lang='ru')
IndexError: list index out of range
"
Traceback (most recent call last):
  File "main.py", line 303, in <module>
    bot.polling()
  File "/usr/local/lib/python3.5/dist-packages/telebot/__init__.py", line 392, in polling
    self.__threaded_polling(none_stop, interval, timeout)
  File "/usr/local/lib/python3.5/dist-packages/telebot/__init__.py", line 416, in __threaded_polling
    self.worker_pool.raise_exceptions()
  File "/usr/local/lib/python3.5/dist-packages/telebot/util.py", line 109, in raise_exceptions
    six.reraise(self.exc_info[0], self.exc_info[1], self.exc_info[2])
  File "/usr/lib/python3/dist-packages/six.py", line 686, in reraise
    raise value
  File "/usr/local/lib/python3.5/dist-packages/telebot/util.py", line 60, in run
    task(*args, **kwargs)
  File "main.py", line 81, in listener
    text_to_speech(m)
  File "main.py", line 120, in text_to_speech
    tts = gTTS(strs[1], lang='ru')
IndexError: list index out of range
2020-05-29 11:12:02,746 (util.py:66 PollingThread) ERROR - TeleBot: "ApiException occurred, args=('A request to the Telegram API was unsuccessful. The server returned HTTP 409 Conflict. Response body:\n[b\'{"ok":false,"error_code":409,"description":"Conflict: terminated by other getUpdates request; make sure that only one bot instance is running"}\']',)
Traceback (most recent call last):
  File "/usr/local/lib/python3.5/dist-packages/telebot/util.py", line 60, in run
    task(*args, **kwargs)
  File "/usr/local/lib/python3.5/dist-packages/telebot/__init__.py", line 279, in __retrieve_updates
    updates = self.get_updates(offset=(self.last_update_id + 1), timeout=timeout)
  File "/usr/local/lib/python3.5/dist-packages/telebot/__init__.py", line 249, in get_updates
    json_updates = apihelper.get_updates(self.token, offset, limit, timeout, allowed_updates)
  File "/usr/local/lib/python3.5/dist-packages/telebot/apihelper.py", line 194, in get_updates
    return _make_request(token, method_url, params=payload)
  File "/usr/local/lib/python3.5/dist-packages/telebot/apihelper.py", line 60, in _make_request
    return _check_result(method_name, result)['result']
  File "/usr/local/lib/python3.5/dist-packages/telebot/apihelper.py", line 79, in _check_result
    raise ApiException(msg, method_name, result)
telebot.apihelper.ApiException: A request to the Telegram API was unsuccessful. The server returned HTTP 409 Conflict. Response body:
[b'{"ok":false,"error_code":409,"description":"Conflict: terminated by other getUpdates request; make sure that only one bot instance is running"}']
"
2020-05-29 11:12:02,746 (__init__.py:420 MainThread) ERROR - TeleBot: "A request to the Telegram API was unsuccessful. The server returned HTTP 409 Conflict. Response body:
[b'{"ok":false,"error_code":409,"description":"Conflict: terminated by other getUpdates request; make sure that only one bot instance is running"}']"
2020-05-29 13:43:10,958 (util.py:66 PollingThread) ERROR - TeleBot: "ApiException occurred, args=('A request to the Telegram API was unsuccessful. The server returned HTTP 409 Conflict. Response body:\n[b\'{"ok":false,"error_code":409,"description":"Conflict: terminated by other getUpdates request; make sure that only one bot instance is running"}\']',)
Traceback (most recent call last):
  File "/usr/local/lib/python3.5/dist-packages/telebot/util.py", line 60, in run
    task(*args, **kwargs)
  File "/usr/local/lib/python3.5/dist-packages/telebot/__init__.py", line 279, in __retrieve_updates
    updates = self.get_updates(offset=(self.last_update_id + 1), timeout=timeout)
  File "/usr/local/lib/python3.5/dist-packages/telebot/__init__.py", line 249, in get_updates
    json_updates = apihelper.get_updates(self.token, offset, limit, timeout, allowed_updates)
  File "/usr/local/lib/python3.5/dist-packages/telebot/apihelper.py", line 194, in get_updates
    return _make_request(token, method_url, params=payload)
  File "/usr/local/lib/python3.5/dist-packages/telebot/apihelper.py", line 60, in _make_request
    return _check_result(method_name, result)['result']
  File "/usr/local/lib/python3.5/dist-packages/telebot/apihelper.py", line 79, in _check_result
    raise ApiException(msg, method_name, result)
telebot.apihelper.ApiException: A request to the Telegram API was unsuccessful. The server returned HTTP 409 Conflict. Response body:
[b'{"ok":false,"error_code":409,"description":"Conflict: terminated by other getUpdates request; make sure that only one bot instance is running"}']
"
2020-05-29 13:43:10,964 (__init__.py:420 MainThread) ERROR - TeleBot: "A request to the Telegram API was unsuccessful. The server returned HTTP 409 Conflict. Response body:
[b'{"ok":false,"error_code":409,"description":"Conflict: terminated by other getUpdates request; make sure that only one bot instance is running"}']"
2020-05-29 13:44:28,686 (util.py:66 WorkerThread1) ERROR - TeleBot: "AssertionError occurred, args=('No text to speak',)
Traceback (most recent call last):
  File "/usr/local/lib/python3.5/dist-packages/telebot/util.py", line 60, in run
    task(*args, **kwargs)
  File "main.py", line 84, in listener
    bot_say(m)
  File "main.py", line 137, in bot_say
    tts = gTTS(strs[1], lang='ru')
  File "/usr/local/lib/python3.5/dist-packages/gtts/tts.py", line 120, in __init__
    assert text, 'No text to speak'
AssertionError: No text to speak
"
Traceback (most recent call last):
  File "main.py", line 339, in <module>
    bot.polling()
  File "/usr/local/lib/python3.5/dist-packages/telebot/__init__.py", line 392, in polling
    self.__threaded_polling(none_stop, interval, timeout)
  File "/usr/local/lib/python3.5/dist-packages/telebot/__init__.py", line 416, in __threaded_polling
    self.worker_pool.raise_exceptions()
  File "/usr/local/lib/python3.5/dist-packages/telebot/util.py", line 109, in raise_exceptions
    six.reraise(self.exc_info[0], self.exc_info[1], self.exc_info[2])
  File "/usr/lib/python3/dist-packages/six.py", line 686, in reraise
    raise value
  File "/usr/local/lib/python3.5/dist-packages/telebot/util.py", line 60, in run
    task(*args, **kwargs)
  File "main.py", line 84, in listener
    bot_say(m)
  File "main.py", line 137, in bot_say
    tts = gTTS(strs[1], lang='ru')
  File "/usr/local/lib/python3.5/dist-packages/gtts/tts.py", line 120, in __init__
    assert text, 'No text to speak'
AssertionError: No text to speak
2020-05-29 13:48:05,668 (util.py:66 PollingThread) ERROR - TeleBot: "ApiException occurred, args=('A request to the Telegram API was unsuccessful. The server returned HTTP 409 Conflict. Response body:\n[b\'{"ok":false,"error_code":409,"description":"Conflict: terminated by other getUpdates request; make sure that only one bot instance is running"}\']',)
Traceback (most recent call last):
  File "/usr/local/lib/python3.5/dist-packages/telebot/util.py", line 60, in run
    task(*args, **kwargs)
  File "/usr/local/lib/python3.5/dist-packages/telebot/__init__.py", line 279, in __retrieve_updates
    updates = self.get_updates(offset=(self.last_update_id + 1), timeout=timeout)
  File "/usr/local/lib/python3.5/dist-packages/telebot/__init__.py", line 249, in get_updates
    json_updates = apihelper.get_updates(self.token, offset, limit, timeout, allowed_updates)
  File "/usr/local/lib/python3.5/dist-packages/telebot/apihelper.py", line 194, in get_updates
    return _make_request(token, method_url, params=payload)
  File "/usr/local/lib/python3.5/dist-packages/telebot/apihelper.py", line 60, in _make_request
    return _check_result(method_name, result)['result']
  File "/usr/local/lib/python3.5/dist-packages/telebot/apihelper.py", line 79, in _check_result
    raise ApiException(msg, method_name, result)
telebot.apihelper.ApiException: A request to the Telegram API was unsuccessful. The server returned HTTP 409 Conflict. Response body:
[b'{"ok":false,"error_code":409,"description":"Conflict: terminated by other getUpdates request; make sure that only one bot instance is running"}']
"
2020-05-29 13:48:05,668 (__init__.py:420 MainThread) ERROR - TeleBot: "A request to the Telegram API was unsuccessful. The server returned HTTP 409 Conflict. Response body:
[b'{"ok":false,"error_code":409,"description":"Conflict: terminated by other getUpdates request; make sure that only one bot instance is running"}']"
2020-06-01 23:16:19,357 (util.py:66 PollingThread) ERROR - TeleBot: "ApiException occurred, args=('A request to the Telegram API was unsuccessful. The server returned HTTP 500 Internal Server Error. Response body:\n[b\'{"ok":false,"error_code":500,"description":"Internal Server Error: restart"}\']',)
Traceback (most recent call last):
  File "/usr/local/lib/python3.5/dist-packages/telebot/util.py", line 60, in run
    task(*args, **kwargs)
  File "/usr/local/lib/python3.5/dist-packages/telebot/__init__.py", line 279, in __retrieve_updates
    updates = self.get_updates(offset=(self.last_update_id + 1), timeout=timeout)
  File "/usr/local/lib/python3.5/dist-packages/telebot/__init__.py", line 249, in get_updates
    json_updates = apihelper.get_updates(self.token, offset, limit, timeout, allowed_updates)
  File "/usr/local/lib/python3.5/dist-packages/telebot/apihelper.py", line 194, in get_updates
    return _make_request(token, method_url, params=payload)
  File "/usr/local/lib/python3.5/dist-packages/telebot/apihelper.py", line 60, in _make_request
    return _check_result(method_name, result)['result']
  File "/usr/local/lib/python3.5/dist-packages/telebot/apihelper.py", line 79, in _check_result
    raise ApiException(msg, method_name, result)
telebot.apihelper.ApiException: A request to the Telegram API was unsuccessful. The server returned HTTP 500 Internal Server Error. Response body:
[b'{"ok":false,"error_code":500,"description":"Internal Server Error: restart"}']
"
2020-06-01 23:16:19,358 (__init__.py:420 MainThread) ERROR - TeleBot: "A request to the Telegram API was unsuccessful. The server returned HTTP 500 Internal Server Error. Response body:
[b'{"ok":false,"error_code":500,"description":"Internal Server Error: restart"}']"
2020-06-02 07:14:41,685 (util.py:66 PollingThread) ERROR - TeleBot: "ApiException occurred, args=('A request to the Telegram API was unsuccessful. The server returned HTTP 409 Conflict. Response body:\n[b\'{"ok":false,"error_code":409,"description":"Conflict: terminated by other getUpdates request; make sure that only one bot instance is running"}\']',)
Traceback (most recent call last):
  File "/usr/local/lib/python3.5/dist-packages/telebot/util.py", line 60, in run
    task(*args, **kwargs)
  File "/usr/local/lib/python3.5/dist-packages/telebot/__init__.py", line 279, in __retrieve_updates
    updates = self.get_updates(offset=(self.last_update_id + 1), timeout=timeout)
  File "/usr/local/lib/python3.5/dist-packages/telebot/__init__.py", line 249, in get_updates
    json_updates = apihelper.get_updates(self.token, offset, limit, timeout, allowed_updates)
  File "/usr/local/lib/python3.5/dist-packages/telebot/apihelper.py", line 194, in get_updates
    return _make_request(token, method_url, params=payload)
  File "/usr/local/lib/python3.5/dist-packages/telebot/apihelper.py", line 60, in _make_request
    return _check_result(method_name, result)['result']
  File "/usr/local/lib/python3.5/dist-packages/telebot/apihelper.py", line 79, in _check_result
    raise ApiException(msg, method_name, result)
telebot.apihelper.ApiException: A request to the Telegram API was unsuccessful. The server returned HTTP 409 Conflict. Response body:
[b'{"ok":false,"error_code":409,"description":"Conflict: terminated by other getUpdates request; make sure that only one bot instance is running"}']
"
2020-06-02 07:14:41,689 (__init__.py:420 MainThread) ERROR - TeleBot: "A request to the Telegram API was unsuccessful. The server returned HTTP 409 Conflict. Response body:
[b'{"ok":false,"error_code":409,"description":"Conflict: terminated by other getUpdates request; make sure that only one bot instance is running"}']"
2020-06-02 07:55:25,768 (util.py:66 PollingThread) ERROR - TeleBot: "ApiException occurred, args=('A request to the Telegram API was unsuccessful. The server returned HTTP 409 Conflict. Response body:\n[b\'{"ok":false,"error_code":409,"description":"Conflict: terminated by other getUpdates request; make sure that only one bot instance is running"}\']',)
Traceback (most recent call last):
  File "/usr/local/lib/python3.5/dist-packages/telebot/util.py", line 60, in run
    task(*args, **kwargs)
  File "/usr/local/lib/python3.5/dist-packages/telebot/__init__.py", line 279, in __retrieve_updates
    updates = self.get_updates(offset=(self.last_update_id + 1), timeout=timeout)
  File "/usr/local/lib/python3.5/dist-packages/telebot/__init__.py", line 249, in get_updates
    json_updates = apihelper.get_updates(self.token, offset, limit, timeout, allowed_updates)
  File "/usr/local/lib/python3.5/dist-packages/telebot/apihelper.py", line 194, in get_updates
    return _make_request(token, method_url, params=payload)
  File "/usr/local/lib/python3.5/dist-packages/telebot/apihelper.py", line 60, in _make_request
    return _check_result(method_name, result)['result']
  File "/usr/local/lib/python3.5/dist-packages/telebot/apihelper.py", line 79, in _check_result
    raise ApiException(msg, method_name, result)
telebot.apihelper.ApiException: A request to the Telegram API was unsuccessful. The server returned HTTP 409 Conflict. Response body:
[b'{"ok":false,"error_code":409,"description":"Conflict: terminated by other getUpdates request; make sure that only one bot instance is running"}']
"
2020-06-02 07:55:25,769 (__init__.py:420 MainThread) ERROR - TeleBot: "A request to the Telegram API was unsuccessful. The server returned HTTP 409 Conflict. Response body:
[b'{"ok":false,"error_code":409,"description":"Conflict: terminated by other getUpdates request; make sure that only one bot instance is running"}']"
2020-06-03 19:17:24,984 (util.py:66 PollingThread) ERROR - TeleBot: "AttributeError occurred, args=("'NoneType' object has no attribute 'lower'",)
Traceback (most recent call last):
  File "/usr/local/lib/python3.5/dist-packages/telebot/util.py", line 60, in run
    task(*args, **kwargs)
  File "/usr/local/lib/python3.5/dist-packages/telebot/__init__.py", line 280, in __retrieve_updates
    self.process_new_updates(updates)
  File "/usr/local/lib/python3.5/dist-packages/telebot/__init__.py", line 317, in process_new_updates
    self.process_new_messages(new_messages)
  File "/usr/local/lib/python3.5/dist-packages/telebot/__init__.py", line 339, in process_new_messages
    self._notify_command_handlers(self.message_handlers, new_messages)
  File "/usr/local/lib/python3.5/dist-packages/telebot/__init__.py", line 1801, in _notify_command_handlers
    if self._test_message_handler(message_handler, message):
  File "/usr/local/lib/python3.5/dist-packages/telebot/__init__.py", line 1769, in _test_message_handler
    if not self._test_filter(filter, filter_value, message):
  File "/usr/local/lib/python3.5/dist-packages/telebot/__init__.py", line 1790, in _test_filter
    return test_cases.get(filter, lambda msg: False)(message)
  File "/usr/local/lib/python3.5/dist-packages/telebot/__init__.py", line 1787, in <lambda>
    'func': lambda msg: filter_value(msg)
  File "main.py", line 298, in <lambda>
    @bot.message_handler(func=lambda message: "сука" in message.text.lower())
AttributeError: 'NoneType' object has no attribute 'lower'
"
Traceback (most recent call last):
  File "main.py", line 357, in <module>
    bot.polling()
  File "/usr/local/lib/python3.5/dist-packages/telebot/__init__.py", line 392, in polling
    self.__threaded_polling(none_stop, interval, timeout)
  File "/usr/local/lib/python3.5/dist-packages/telebot/__init__.py", line 415, in __threaded_polling
    polling_thread.raise_exceptions()
  File "/usr/local/lib/python3.5/dist-packages/telebot/util.py", line 79, in raise_exceptions
    six.reraise(self.exc_info[0], self.exc_info[1], self.exc_info[2])
  File "/usr/lib/python3/dist-packages/six.py", line 686, in reraise
    raise value
  File "/usr/local/lib/python3.5/dist-packages/telebot/util.py", line 60, in run
    task(*args, **kwargs)
  File "/usr/local/lib/python3.5/dist-packages/telebot/__init__.py", line 280, in __retrieve_updates
    self.process_new_updates(updates)
  File "/usr/local/lib/python3.5/dist-packages/telebot/__init__.py", line 317, in process_new_updates
    self.process_new_messages(new_messages)
  File "/usr/local/lib/python3.5/dist-packages/telebot/__init__.py", line 339, in process_new_messages
    self._notify_command_handlers(self.message_handlers, new_messages)
  File "/usr/local/lib/python3.5/dist-packages/telebot/__init__.py", line 1801, in _notify_command_handlers
    if self._test_message_handler(message_handler, message):
  File "/usr/local/lib/python3.5/dist-packages/telebot/__init__.py", line 1769, in _test_message_handler
    if not self._test_filter(filter, filter_value, message):
  File "/usr/local/lib/python3.5/dist-packages/telebot/__init__.py", line 1790, in _test_filter
    return test_cases.get(filter, lambda msg: False)(message)
  File "/usr/local/lib/python3.5/dist-packages/telebot/__init__.py", line 1787, in <lambda>
    'func': lambda msg: filter_value(msg)
  File "main.py", line 298, in <lambda>
    @bot.message_handler(func=lambda message: "сука" in message.text.lower())
AttributeError: 'NoneType' object has no attribute 'lower'
2020-06-06 20:05:41,010 (util.py:66 PollingThread) ERROR - TeleBot: "ReadTimeout occurred, args=(ReadTimeoutError("HTTPSConnectionPool(host='api.telegram.org', port=443): Read timed out. (read timeout=30)",),)
Traceback (most recent call last):
  File "/usr/lib/python3/dist-packages/urllib3/connectionpool.py", line 376, in _make_request
    httplib_response = conn.getresponse(buffering=True)
TypeError: getresponse() got an unexpected keyword argument 'buffering'

During handling of the above exception, another exception occurred:

Traceback (most recent call last):
  File "/usr/lib/python3/dist-packages/urllib3/connectionpool.py", line 378, in _make_request
    httplib_response = conn.getresponse()
  File "/usr/lib/python3.5/http/client.py", line 1225, in getresponse
    response.begin()
  File "/usr/lib/python3.5/http/client.py", line 307, in begin
    version, status, reason = self._read_status()
  File "/usr/lib/python3.5/http/client.py", line 268, in _read_status
    line = str(self.fp.readline(_MAXLINE + 1), "iso-8859-1")
  File "/usr/lib/python3.5/socket.py", line 575, in readinto
    return self._sock.recv_into(b)
  File "/usr/lib/python3.5/ssl.py", line 929, in recv_into
    return self.read(nbytes, buffer)
  File "/usr/lib/python3.5/ssl.py", line 791, in read
    return self._sslobj.read(len, buffer)
  File "/usr/lib/python3.5/ssl.py", line 575, in read
    v = self._sslobj.read(len, buffer)
socket.timeout: The read operation timed out

During handling of the above exception, another exception occurred:

Traceback (most recent call last):
  File "/usr/lib/python3/dist-packages/requests/adapters.py", line 376, in send
    timeout=timeout
  File "/usr/lib/python3/dist-packages/urllib3/connectionpool.py", line 609, in urlopen
    _stacktrace=sys.exc_info()[2])
  File "/usr/lib/python3/dist-packages/urllib3/util/retry.py", line 247, in increment
    raise six.reraise(type(error), error, _stacktrace)
  File "/usr/lib/python3/dist-packages/six.py", line 686, in reraise
    raise value
  File "/usr/lib/python3/dist-packages/urllib3/connectionpool.py", line 559, in urlopen
    body=body, headers=headers)
  File "/usr/lib/python3/dist-packages/urllib3/connectionpool.py", line 380, in _make_request
    self._raise_timeout(err=e, url=url, timeout_value=read_timeout)
  File "/usr/lib/python3/dist-packages/urllib3/connectionpool.py", line 308, in _raise_timeout
    raise ReadTimeoutError(self, url, "Read timed out. (read timeout=%s)" % timeout_value)
requests.packages.urllib3.exceptions.ReadTimeoutError: HTTPSConnectionPool(host='api.telegram.org', port=443): Read timed out. (read timeout=30)

During handling of the above exception, another exception occurred:

Traceback (most recent call last):
  File "/usr/local/lib/python3.5/dist-packages/telebot/util.py", line 60, in run
    task(*args, **kwargs)
  File "/usr/local/lib/python3.5/dist-packages/telebot/__init__.py", line 279, in __retrieve_updates
    updates = self.get_updates(offset=(self.last_update_id + 1), timeout=timeout)
  File "/usr/local/lib/python3.5/dist-packages/telebot/__init__.py", line 249, in get_updates
    json_updates = apihelper.get_updates(self.token, offset, limit, timeout, allowed_updates)
  File "/usr/local/lib/python3.5/dist-packages/telebot/apihelper.py", line 194, in get_updates
    return _make_request(token, method_url, params=payload)
  File "/usr/local/lib/python3.5/dist-packages/telebot/apihelper.py", line 58, in _make_request
    timeout=(connect_timeout, read_timeout), proxies=proxy)
  File "/usr/lib/python3/dist-packages/requests/sessions.py", line 468, in request
    resp = self.send(prep, **send_kwargs)
  File "/usr/lib/python3/dist-packages/requests/sessions.py", line 576, in send
    r = adapter.send(request, **kwargs)
  File "/usr/lib/python3/dist-packages/requests/adapters.py", line 449, in send
    raise ReadTimeout(e, request=request)
requests.exceptions.ReadTimeout: HTTPSConnectionPool(host='api.telegram.org', port=443): Read timed out. (read timeout=30)
"
Traceback (most recent call last):
  File "/usr/lib/python3/dist-packages/urllib3/connectionpool.py", line 376, in _make_request
    httplib_response = conn.getresponse(buffering=True)
TypeError: getresponse() got an unexpected keyword argument 'buffering'

During handling of the above exception, another exception occurred:

Traceback (most recent call last):
  File "/usr/lib/python3/dist-packages/urllib3/connectionpool.py", line 378, in _make_request
    httplib_response = conn.getresponse()
  File "/usr/lib/python3.5/http/client.py", line 1225, in getresponse
    response.begin()
  File "/usr/lib/python3.5/http/client.py", line 307, in begin
    version, status, reason = self._read_status()
  File "/usr/lib/python3.5/http/client.py", line 268, in _read_status
    line = str(self.fp.readline(_MAXLINE + 1), "iso-8859-1")
  File "/usr/lib/python3.5/socket.py", line 575, in readinto
    return self._sock.recv_into(b)
  File "/usr/lib/python3.5/ssl.py", line 929, in recv_into
    return self.read(nbytes, buffer)
  File "/usr/lib/python3.5/ssl.py", line 791, in read
    return self._sslobj.read(len, buffer)
  File "/usr/lib/python3.5/ssl.py", line 575, in read
    v = self._sslobj.read(len, buffer)
socket.timeout: The read operation timed out

During handling of the above exception, another exception occurred:

Traceback (most recent call last):
  File "/usr/lib/python3/dist-packages/requests/adapters.py", line 376, in send
    timeout=timeout
  File "/usr/lib/python3/dist-packages/urllib3/connectionpool.py", line 609, in urlopen
    _stacktrace=sys.exc_info()[2])
  File "/usr/lib/python3/dist-packages/urllib3/util/retry.py", line 247, in increment
    raise six.reraise(type(error), error, _stacktrace)
  File "/usr/lib/python3/dist-packages/six.py", line 686, in reraise
    raise value
  File "/usr/lib/python3/dist-packages/urllib3/connectionpool.py", line 559, in urlopen
    body=body, headers=headers)
  File "/usr/lib/python3/dist-packages/urllib3/connectionpool.py", line 380, in _make_request
    self._raise_timeout(err=e, url=url, timeout_value=read_timeout)
  File "/usr/lib/python3/dist-packages/urllib3/connectionpool.py", line 308, in _raise_timeout
    raise ReadTimeoutError(self, url, "Read timed out. (read timeout=%s)" % timeout_value)
requests.packages.urllib3.exceptions.ReadTimeoutError: HTTPSConnectionPool(host='api.telegram.org', port=443): Read timed out. (read timeout=30)

During handling of the above exception, another exception occurred:

Traceback (most recent call last):
  File "main.py", line 357, in <module>
    bot.polling()
  File "/usr/local/lib/python3.5/dist-packages/telebot/__init__.py", line 392, in polling
    self.__threaded_polling(none_stop, interval, timeout)
  File "/usr/local/lib/python3.5/dist-packages/telebot/__init__.py", line 415, in __threaded_polling
    polling_thread.raise_exceptions()
  File "/usr/local/lib/python3.5/dist-packages/telebot/util.py", line 79, in raise_exceptions
    six.reraise(self.exc_info[0], self.exc_info[1], self.exc_info[2])
  File "/usr/lib/python3/dist-packages/six.py", line 686, in reraise
    raise value
  File "/usr/local/lib/python3.5/dist-packages/telebot/util.py", line 60, in run
    task(*args, **kwargs)
  File "/usr/local/lib/python3.5/dist-packages/telebot/__init__.py", line 279, in __retrieve_updates
    updates = self.get_updates(offset=(self.last_update_id + 1), timeout=timeout)
  File "/usr/local/lib/python3.5/dist-packages/telebot/__init__.py", line 249, in get_updates
    json_updates = apihelper.get_updates(self.token, offset, limit, timeout, allowed_updates)
  File "/usr/local/lib/python3.5/dist-packages/telebot/apihelper.py", line 194, in get_updates
    return _make_request(token, method_url, params=payload)
  File "/usr/local/lib/python3.5/dist-packages/telebot/apihelper.py", line 58, in _make_request
    timeout=(connect_timeout, read_timeout), proxies=proxy)
  File "/usr/lib/python3/dist-packages/requests/sessions.py", line 468, in request
    resp = self.send(prep, **send_kwargs)
  File "/usr/lib/python3/dist-packages/requests/sessions.py", line 576, in send
    r = adapter.send(request, **kwargs)
  File "/usr/lib/python3/dist-packages/requests/adapters.py", line 449, in send
    raise ReadTimeout(e, request=request)
requests.exceptions.ReadTimeout: HTTPSConnectionPool(host='api.telegram.org', port=443): Read timed out. (read timeout=30)
